Workbook

Sheet 假设
A1: 假设面板 · 改这里，整表自动重算
A2: 浅蓝字=可编辑输入项。右上角选择情景后，所有下游表格自动切换。 基准参数已用 81 组参数扫描按行业基准带校准（见 calibrate.py）。
A4: 当前情景 | B4: 基准 | C4: ← 下拉切换
A6: 产品与定价
A7: 每席位月费 (US$) | B7: 29 | C7: 29 | D7: 29 | E7: 客户给定 $29
A8: M1 平均席位数/客户 | B8: 12 | C8: 12 | D8: 12 | E8: SMB 团队起步规模
A9: M36 平均席位数/客户 | B9: 13 | C9: 17 | D9: 18 | E9: 随客户成长
A10: 席位净扩张率 (月) | B10: 0.0075 | C10: 0.0185 | D10: 0.025 | E10: NRR 的唯一来源，对模型最敏感
A11: 获客漏斗
A12: M36 月注册量 | B12: 565 | C12: 1030 | D12: 1400 | E12: PLG 流量规模
A13: PLG 注册→付费转化 (M36) | B13: 0.029 | C13: 0.04 | D13: 0.05 | E13: 行业 3–5%
A14: 单注册成本 (US$) | B14: 30 | C14: 30 | D14: 26 | E14: 驱动营销预算 → CAC 是产出不是输入
A15: M36 AE 人数 | B15: 5 | C15: 5 | D15: 5 | E15: 销售辅助获客产能
A16: M36 AE 人效 (客/人/月) | B16: 1.3 | C16: 2.1 | D16: 2.7 | E16: SMB 小单成单慢，早期偏低
A17: 留存与合同结构
A18: PLG 客月流失率 | B18: 0.082 | C18: 0.062 | D18: 0.052 | E18: 低价自助带 5–8%/月
A19: 销售客月流失率 | B19: 0.028 | C19: 0.018 | D19: 0.015 | E19: 年约带 1–2%/月
A20: PLG 客年约自升级率 (月) | B20: 0.1 | C20: 0.26 | D20: 0.34 | E20: 把月付客转成年约可砍半流失
A21: 年约客回退月付率 (月) | B21: 0.004 | C21: 0.004 | D21: 0.004 | E21: 年约也会掉回月付
A22: M36 销售辅助客占新客比 | B22: 0.38 | C22: 0.62 | D22: 0.7 | E22: 年约销售客占比
A23: 成本结构
A24: 服务器固定成本 (月) | B24: 2200 | C24: 2200 | D24: 2200
A25: 单客户服务器成本 (月) | B25: 8 | C25: 8 | D25: 8
A26: 支付通道费率 | B26: 0.029 | C26: 0.029 | D26: 0.029 | E26: Stripe 约 2.9%
A27: 营销固定项目 (月) | B27: 4000 | C27: 4000 | D27: 4000 | E27: 品牌/活动/工具
A28: 办公与行政 (月) | B28: 3500 | C28: 3500 | D28: 3500
A29: 客户支持工具 (月) | B29: 1200 | C29: 1200 | D29: 1200 | E29: 客户成功工具/知识库
A30: 资本开支占收入比 | B30: 0.012 | C30: 0.012 | D30: 0.012 | E30: 轻资产，约 1.2%
A31: M36 团队总人数 | B31: 41 | C31: 34 | D31: 34 | E31: 由分职能编制表加总
A32: 融资
A33: 种子轮金额 | B33: 3500000 | C33: 3500000 | D33: 3500000 | E33: Carta SaaS 种子中位 $4.1M
A34: 种子轮投后 | B34: 20000000 | C34: 20000000 | D34: 20000000
A35: A 轮目标规模 | B35: 12000000 | C35: 12000000 | D35: 12000000 | E35: Carta A 轮中位 $12M
A36: A 轮打款月份 | B36: 0 | C36: 0 | D36: 0 | E36: 派生量：ARR 过 $1M 的月份（基准 M18），改这个值需同步模型
A38: ▼ 选中的情景值（公式引用，改 B4 即变）
A39: a_round_month | B39: =INDEX(B36:D36,1,MATCH($B$4,B$6:B$6,0))

Sheet 月度模型
A1: 月度模型 · 36 个月（活公式）
A2: 所有单元格引用「假设」页，随情景切换与假设修改自动重算。 口径:MRR=期末客户数×席位数×$29;ARR=MRR×12;CAC 回收期用毛利口径。
A4: 月份 | B4: 注册量 | C4: PLG新客 | D4: 销售新客 | E4: 新客合计 | F4: 流失客户 | G4: 期末客户数 | H4: 期末席位数 | I4: ARPU | J4: MRR | K4: ARR | L4: 收入 | M4: 服务器+支付 | N4: 客户支持 | O4: 毛利 | P4: 毛利率 | Q4: 研发+产品 | R4: 销售与市场 | S4: 管理行政 | T4: EBITDA | U4: 经营现金流 | V4: 期末现金 | W4: 营运资本变动 | X4: 税金 | Y4: A轮回款 | Z4: 资本开支
A5: 1 | B5: =INDEX(注册量_三情景!$B$2:$D$2,1,MATCH(假设!$B$4,{"悲观","基准","乐观"},0)) | C5: =B5*INDEX(转化率_三情景!$B$2:$D$2,1,MATCH(假设!$B$4,{"悲观","基准","乐观"},0)) | D5: =INDEX(AE数_三情景!$B$2:$D$2,1,MATCH(假设!$B$4,{"悲观","基准","乐观"},0))*INDEX(AE人效_三情景!$B$2:$D$2,1,MATCH(假设!$B$4,{"悲观","基准","乐观"},0)) | E5: =C5+D5 | F5: =INDEX(流失_三情景!$B$2:$D$2,1,MATCH(假设!$B$4,{"悲观","基准","乐观"},0)) | G5: =INDEX(客户数_三情景!$B$2:$D$2,1,MATCH(假设!$B$4,{"悲观","基准","乐观"},0)) | H5: =INDEX(席位数_三情景!$B$2:$D$2,1,MATCH(假设!$B$4,{"悲观","基准","乐观"},0)) | I5: =IF(G5=0,0,L5/G5) | J5: =H5*假设!$B$7 | K5: =J5*12 | L5: =J5 | M5: =假设!$B$24+假设!$B$25*G5+L5*假设!$B$26+假设!$B$29 | N5: =INDEX(客户支持_三情景!$B$2:$D$2,1,MATCH(假设!$B$4,{"悲观","基准","乐观"},0)) | O5: =L5-M5-N5 | P5: =IF(L5=0,0,O5/L5) | Q5: =INDEX(研发_三情景!$B$2:$D$2,1,MATCH(假设!$B$4,{"悲观","基准","乐观"},0)) | R5: =INDEX(销售市场_三情景!$B$2:$D$2,1,MATCH(假设!$B$4,{"悲观","基准","乐观"},0)) | S5: =INDEX(管理行政_三情景!$B$2:$D$2,1,MATCH(假设!$B$4,{"悲观","基准","乐观"},0)) | T5: =O5-Q5-R5-S5 | U5: =T5-W5-X5 | V5: =假设!$B$33+SUM($U$5:U5)+SUM($Y$5:Y5)-SUM($Z$5:Z5) | W5: =INDEX(营运资本_三情景!$B$2:$D$2,1,MATCH(假设!$B$4,{"悲观","基准","乐观"},0)) | X5: =INDEX(税金_三情景!$B$2:$D$2,1,MATCH(假设!$B$4,{"悲观","基准","乐观"},0)) | Y5: =IF($A5=18,假设!$B$35,0) | Z5: =L5*假设!$B$30
A6: 2 | B6: =INDEX(注册量_三情景!$B$3:$D$3,1,MATCH(假设!$B$4,{"悲观","基准","乐观"},0)) | C6: =B6*INDEX(转化率_三情景!$B$3:$D$3,1,MATCH(假设!$B$4,{"悲观","基准","乐观"},0)) | D6: =INDEX(AE数_三情景!$B$3:$D$3,1,MATCH(假设!$B$4,{"悲观","基准","乐观"},0))*INDEX(AE人效_三情景!$B$3:$D$3,1,MATCH(假设!$B$4,{"悲观","基准","乐观"},0)) | E6: =C6+D6 | F6: =INDEX(流失_三情景!$B$3:$D$3,1,MATCH(假设!$B$4,{"悲观","基准","乐观"},0)) | G6: =INDEX(客户数_三情景!$B$3:$D$3,1,MATCH(假设!$B$4,{"悲观","基准","乐观"},0)) | H6: =INDEX(席位数_三情景!$B$3:$D$3,1,MATCH(假设!$B$4,{"悲观","基准","乐观"},0)) | I6: =IF(G6=0,0,L6/G6) | J6: =H6*假设!$B$7 | K6: =J6*12 | L6: =J6 | M6: =假设!$B$24+假设!$B$25*G6+L6*假设!$B$26+假设!$B$29 | N6: =INDEX(客户支持_三情景!$B$3:$D$3,1,MATCH(假设!$B$4,{"悲观","基准","乐观"},0)) | O6: =L6-M6-N6 | P6: =IF(L6=0,0,O6/L6) | Q6: =INDEX(研发_三情景!$B$3:$D$3,1,MATCH(假设!$B$4,{"悲观","基准","乐观"},0)) | R6: =INDEX(销售市场_三情景!$B$3:$D$3,1,MATCH(假设!$B$4,{"悲观","基准","乐观"},0)) | S6: =INDEX(管理行政_三情景!$B$3:$D$3,1,MATCH(假设!$B$4,{"悲观","基准","乐观"},0)) | T6: =O6-Q6-R6-S6 | U6: =T6-W6-X6 | V6: =假设!$B$33+SUM($U$5:U6)+SUM($Y$5:Y6)-SUM($Z$5:Z6) | W6: =INDEX(营运资本_三情景!$B$3:$D$3,1,MATCH(假设!$B$4,{"悲观","基准","乐观"},0)) | X6: =INDEX(税金_三情景!$B$3:$D$3,1,MATCH(假设!$B$4,{"悲观","基准","乐观"},0)) | Y6: =IF($A6=18,假设!$B$35,0) | Z6: =L6*假设!$B$30
A7: 3 | B7: =INDEX(注册量_三情景!$B$4:$D$4,1,MATCH(假设!$B$4,{"悲观","基准","乐观"},0)) | C7: =B7*INDEX(转化率_三情景!$B$4:$D$4,1,MATCH(假设!$B$4,{"悲观","基准","乐观"},0)) | D7: =INDEX(AE数_三情景!$B$4:$D$4,1,MATCH(假设!$B$4,{"悲观","基准","乐观"},0))*INDEX(AE人效_三情景!$B$4:$D$4,1,MATCH(假设!$B$4,{"悲观","基准","乐观"},0)) | E7: =C7+D7 | F7: =INDEX(流失_三情景!$B$4:$D$4,1,MATCH(假设!$B$4,{"悲观","基准","乐观"},0)) | G7: =INDEX(客户数_三情景!$B$4:$D$4,1,MATCH(假设!$B$4,{"悲观","基准","乐观"},0)) | H7: =INDEX(席位数_三情景!$B$4:$D$4,1,MATCH(假设!$B$4,{"悲观","基准","乐观"},0)) | I7: =IF(G7=0,0,L7/G7) | J7: =H7*假设!$B$7 | K7: =J7*12 | L7: =J7 | M7: =假设!$B$24+假设!$B$25*G7+L7*假设!$B$26+假设!$B$29 | N7: =INDEX(客户支持_三情景!$B$4:$D$4,1,MATCH(假设!$B$4,{"悲观","基准","乐观"},0)) | O7: =L7-M7-N7 | P7: =IF(L7=0,0,O7/L7) | Q7: =INDEX(研发_三情景!$B$4:$D$4,1,MATCH(假设!$B$4,{"悲观","基准","乐观"},0)) | R7: =INDEX(销售市场_三情景!$B$4:$D$4,1,MATCH(假设!$B$4,{"悲观","基准","乐观"},0)) | S7: =INDEX(管理行政_三情景!$B$4:$D$4,1,MATCH(假设!$B$4,{"悲观","基准","乐观"},0)) | T7: =O7-Q7-R7-S7 | U7: =T7-W7-X7 | V7: =假设!$B$33+SUM($U$5:U7)+SUM($Y$5:Y7)-SUM($Z$5:Z7) | W7: =INDEX(营运资本_三情景!$B$4:$D$4,1,MATCH(假设!$B$4,{"悲观","基准","乐观"},0)) | X7: =INDEX(税金_三情景!$B$4:$D$4,1,MATCH(假设!$B$4,{"悲观","基准","乐观"},0)) | Y7: =IF($A7=18,假设!$B$35,0) | Z7: =L7*假设!$B$30
A8: 4 | B8: =INDEX(注册量_三情景!$B$5:$D$5,1,MATCH(假设!$B$4,{"悲观","基准","乐观"},0)) | C8: =B8*INDEX(转化率_三情景!$B$5:$D$5,1,MATCH(假设!$B$4,{"悲观","基准","乐观"},0)) | D8: =INDEX(AE数_三情景!$B$5:$D$5,1,MATCH(假设!$B$4,{"悲观","基准","乐观"},0))*INDEX(AE人效_三情景!$B$5:$D$5,1,MATCH(假设!$B$4,{"悲观","基准","乐观"},0)) | E8: =C8+D8 | F8: =INDEX(流失_三情景!$B$5:$D$5,1,MATCH(假设!$B$4,{"悲观","基准","乐观"},0)) | G8: =INDEX(客户数_三情景!$B$5:$D$5,1,MATCH(假设!$B$4,{"悲观","基准","乐观"},0)) | H8: =INDEX(席位数_三情景!$B$5:$D$5,1,MATCH(假设!$B$4,{"悲观","基准","乐观"},0)) | I8: =IF(G8=0,0,L8/G8) | J8: =H8*假设!$B$7 | K8: =J8*12 | L8: =J8 | M8: =假设!$B$24+假设!$B$25*G8+L8*假设!$B$26+假设!$B$29 | N8: =INDEX(客户支持_三情景!$B$5:$D$5,1,MATCH(假设!$B$4,{"悲观","基准","乐观"},0)) | O8: =L8-M8-N8 | P8: =IF(L8=0,0,O8/L8) | Q8: =INDEX(研发_三情景!$B$5:$D$5,1,MATCH(假设!$B$4,{"悲观","基准","乐观"},0)) | R8: =INDEX(销售市场_三情景!$B$5:$D$5,1,MATCH(假设!$B$4,{"悲观","基准","乐观"},0)) | S8: =INDEX(管理行政_三情景!$B$5:$D$5,1,MATCH(假设!$B$4,{"悲观","基准","乐观"},0)) | T8: =O8-Q8-R8-S8 | U8: =T8-W8-X8 | V8: =假设!$B$33+SUM($U$5:U8)+SUM($Y$5:Y8)-SUM($Z$5:Z8) | W8: =INDEX(营运资本_三情景!$B$5:$D$5,1,MATCH(假设!$B$4,{"悲观","基准","乐观"},0)) | X8: =INDEX(税金_三情景!$B$5:$D$5,1,MATCH(假设!$B$4,{"悲观","基准","乐观"},0)) | Y8: =IF($A8=18,假设!$B$35,0) | Z8: =L8*假设!$B$30
A9: 5 | B9: =INDEX(注册量_三情景!$B$6:$D$6,1,MATCH(假设!$B$4,{"悲观","基准","乐观"},0)) | C9: =B9*INDEX(转化率_三情景!$B$6:$D$6,1,MATCH(假设!$B$4,{"悲观","基准","乐观"},0)) | D9: =INDEX(AE数_三情景!$B$6:$D$6,1,MATCH(假设!$B$4,{"悲观","基准","乐观"},0))*INDEX(AE人效_三情景!$B$6:$D$6,1,MATCH(假设!$B$4,{"悲观","基准","乐观"},0)) | E9: =C9+D9 | F9: =INDEX(流失_三情景!$B$6:$D$6,1,MATCH(假设!$B$4,{"悲观","基准","乐观"},0)) | G9: =INDEX(客户数_三情景!$B$6:$D$6,1,MATCH(假设!$B$4,{"悲观","基准","乐观"},0)) | H9: =INDEX(席位数_三情景!$B$6:$D$6,1,MATCH(假设!$B$4,{"悲观","基准","乐观"},0)) | I9: =IF(G9=0,0,L9/G9) | J9: =H9*假设!$B$7 | K9: =J9*12 | L9: =J9 | M9: =假设!$B$24+假设!$B$25*G9+L9*假设!$B$26+假设!$B$29 | N9: =INDEX(客户支持_三情景!$B$6:$D$6,1,MATCH(假设!$B$4,{"悲观","基准","乐观"},0)) | O9: =L9-M9-N9 | P9: =IF(L9=0,0,O9/L9) | Q9: =INDEX(研发_三情景!$B$6:$D$6,1,MATCH(假设!$B$4,{"悲观","基准","乐观"},0)) | R9: =INDEX(销售市场_三情景!$B$6:$D$6,1,MATCH(假设!$B$4,{"悲观","基准","乐观"},0)) | S9: =INDEX(管理行政_三情景!$B$6:$D$6,1,MATCH(假设!$B$4,{"悲观","基准","乐观"},0)) | T9: =O9-Q9-R9-S9 | U9: =T9-W9-X9 | V9: =假设!$B$33+SUM($U$5:U9)+SUM($Y$5:Y9)-SUM($Z$5:Z9) | W9: =INDEX(营运资本_三情景!$B$6:$D$6,1,MATCH(假设!$B$4,{"悲观","基准","乐观"},0)) | X9: =INDEX(税金_三情景!$B$6:$D$6,1,MATCH(假设!$B$4,{"悲观","基准","乐观"},0)) | Y9: =IF($A9=18,假设!$B$35,0) | Z9: =L9*假设!$B$30
A10: 6 | B10: =INDEX(注册量_三情景!$B$7:$D$7,1,MATCH(假设!$B$4,{"悲观","基准","乐观"},0)) | C10: =B10*INDEX(转化率_三情景!$B$7:$D$7,1,MATCH(假设!$B$4,{"悲观","基准","乐观"},0)) | D10: =INDEX(AE数_三情景!$B$7:$D$7,1,MATCH(假设!$B$4,{"悲观","基准","乐观"},0))*INDEX(AE人效_三情景!$B$7:$D$7,1,MATCH(假设!$B$4,{"悲观","基准","乐观"},0)) | E10: =C10+D10 | F10: =INDEX(流失_三情景!$B$7:$D$7,1,MATCH(假设!$B$4,{"悲观","基准","乐观"},0)) | G10: =INDEX(客户数_三情景!$B$7:$D$7,1,MATCH(假设!$B$4,{"悲观","基准","乐观"},0)) | H10: =INDEX(席位数_三情景!$B$7:$D$7,1,MATCH(假设!$B$4,{"悲观","基准","乐观"},0)) | I10: =IF(G10=0,0,L10/G10) | J10: =H10*假设!$B$7 | K10: =J10*12 | L10: =J10 | M10: =假设!$B$24+假设!$B$25*G10+L10*假设!$B$26+假设!$B$29 | N10: =INDEX(客户支持_三情景!$B$7:$D$7,1,MATCH(假设!$B$4,{"悲观","基准","乐观"},0)) | O10: =L10-M10-N10 | P10: =IF(L10=0,0,O10/L10) | Q10: =INDEX(研发_三情景!$B$7:$D$7,1,MATCH(假设!$B$4,{"悲观","基准","乐观"},0)) | R10: =INDEX(销售市场_三情景!$B$7:$D$7,1,MATCH(假设!$B$4,{"悲观","基准","乐观"},0)) | S10: =INDEX(管理行政_三情景!$B$7:$D$7,1,MATCH(假设!$B$4,{"悲观","基准","乐观"},0)) | T10: =O10-Q10-R10-S10 | U10: =T10-W10-X10 | V10: =假设!$B$33+SUM($U$5:U10)+SUM($Y$5:Y10)-SUM($Z$5:Z10) | W10: =INDEX(营运资本_三情景!$B$7:$D$7,1,MATCH(假设!$B$4,{"悲观","基准","乐观"},0)) | X10: =INDEX(税金_三情景!$B$7:$D$7,1,MATCH(假设!$B$4,{"悲观","基准","乐观"},0)) | Y10: =IF($A10=18,假设!$B$35,0) | Z10: =L10*假设!$B$30
A11: 7 | B11: =INDEX(注册量_三情景!$B$8:$D$8,1,MATCH(假设!$B$4,{"悲观","基准","乐观"},0)) | C11: =B11*INDEX(转化率_三情景!$B$8:$D$8,1,MATCH(假设!$B$4,{"悲观","基准","乐观"},0)) | D11: =INDEX(AE数_三情景!$B$8:$D$8,1,MATCH(假设!$B$4,{"悲观","基准","乐观"},0))*INDEX(AE人效_三情景!$B$8:$D$8,1,MATCH(假设!$B$4,{"悲观","基准","乐观"},0)) | E11: =C11+D11 | F11: =INDEX(流失_三情景!$B$8:$D$8,1,MATCH(假设!$B$4,{"悲观","基准","乐观"},0)) | G11: =INDEX(客户数_三情景!$B$8:$D$8,1,MATCH(假设!$B$4,{"悲观","基准","乐观"},0)) | H11: =INDEX(席位数_三情景!$B$8:$D$8,1,MATCH(假设!$B$4,{"悲观","基准","乐观"},0)) | I11: =IF(G11=0,0,L11/G11) | J11: =H11*假设!$B$7 | K11: =J11*12 | L11: =J11 | M11: =假设!$B$24+假设!$B$25*G11+L11*假设!$B$26+假设!$B$29 | N11: =INDEX(客户支持_三情景!$B$8:$D$8,1,MATCH(假设!$B$4,{"悲观","基准","乐观"},0)) | O11: =L11-M11-N11 | P11: =IF(L11=0,0,O11/L11) | Q11: =INDEX(研发_三情景!$B$8:$D$8,1,MATCH(假设!$B$4,{"悲观","基准","乐观"},0)) | R11: =INDEX(销售市场_三情景!$B$8:$D$8,1,MATCH(假设!$B$4,{"悲观","基准","乐观"},0)) | S11: =INDEX(管理行政_三情景!$B$8:$D$8,1,MATCH(假设!$B$4,{"悲观","基准","乐观"},0)) | T11: =O11-Q11-R11-S11 | U11: =T11-W11-X11 | V11: =假设!$B$33+SUM($U$5:U11)+SUM($Y$5:Y11)-SUM($Z$5:Z11) | W11: =INDEX(营运资本_三情景!$B$8:$D$8,1,MATCH(假设!$B$4,{"悲观","基准","乐观"},0)) | X11: =INDEX(税金_三情景!$B$8:$D$8,1,MATCH(假设!$B$4,{"悲观","基准","乐观"},0)) | Y11: =IF($A11=18,假设!$B$35,0) | Z11: =L11*假设!$B$30
A12: 8 | B12: =INDEX(注册量_三情景!$B$9:$D$9,1,MATCH(假设!$B$4,{"悲观","基准","乐观"},0)) | C12: =B12*INDEX(转化率_三情景!$B$9:$D$9,1,MATCH(假设!$B$4,{"悲观","基准","乐观"},0)) | D12: =INDEX(AE数_三情景!$B$9:$D$9,1,MATCH(假设!$B$4,{"悲观","基准","乐观"},0))*INDEX(AE人效_三情景!$B$9:$D$9,1,MATCH(假设!$B$4,{"悲观","基准","乐观"},0)) | E12: =C12+D12 | F12: =INDEX(流失_三情景!$B$9:$D$9,1,MATCH(假设!$B$4,{"悲观","基准","乐观"},0)) | G12: =INDEX(客户数_三情景!$B$9:$D$9,1,MATCH(假设!$B$4,{"悲观","基准","乐观"},0)) | H12: =INDEX(席位数_三情景!$B$9:$D$9,1,MATCH(假设!$B$4,{"悲观","基准","乐观"},0)) | I12: =IF(G12=0,0,L12/G12) | J12: =H12*假设!$B$7 | K12: =J12*12 | L12: =J12 | M12: =假设!$B$24+假设!$B$25*G12+L12*假设!$B$26+假设!$B$29 | N12: =INDEX(客户支持_三情景!$B$9:$D$9,1,MATCH(假设!$B$4,{"悲观","基准","乐观"},0)) | O12: =L12-M12-N12 | P12: =IF(L12=0,0,O12/L12) | Q12: =INDEX(研发_三情景!$B$9:$D$9,1,MATCH(假设!$B$4,{"悲观","基准","乐观"},0)) | R12: =INDEX(销售市场_三情景!$B$9:$D$9,1,MATCH(假设!$B$4,{"悲观","基准","乐观"},0)) | S12: =INDEX(管理行政_三情景!$B$9:$D$9,1,MATCH(假设!$B$4,{"悲观","基准","乐观"},0)) | T12: =O12-Q12-R12-S12 | U12: =T12-W12-X12 | V12: =假设!$B$33+SUM($U$5:U12)+SUM($Y$5:Y12)-SUM($Z$5:Z12) | W12: =INDEX(营运资本_三情景!$B$9:$D$9,1,MATCH(假设!$B$4,{"悲观","基准","乐观"},0)) | X12: =INDEX(税金_三情景!$B$9:$D$9,1,MATCH(假设!$B$4,{"悲观","基准","乐观"},0)) | Y12: =IF($A12=18,假设!$B$35,0) | Z12: =L12*假设!$B$30
A13: 9 | B13: =INDEX(注册量_三情景!$B$10:$D$10,1,MATCH(假设!$B$4,{"悲观","基准","乐观"},0)) | C13: =B13*INDEX(转化率_三情景!$B$10:$D$10,1,MATCH(假设!$B$4,{"悲观","基准","乐观"},0)) | D13: =INDEX(AE数_三情景!$B$10:$D$10,1,MATCH(假设!$B$4,{"悲观","基准","乐观"},0))*INDEX(AE人效_三情景!$B$10:$D$10,1,MATCH(假设!$B$4,{"悲观","基准","乐观"},0)) | E13: =C13+D13 | F13: =INDEX(流失_三情景!$B$10:$D$10,1,MATCH(假设!$B$4,{"悲观","基准","乐观"},0)) | G13: =INDEX(客户数_三情景!$B$10:$D$10,1,MATCH(假设!$B$4,{"悲观","基准","乐观"},0)) | H13: =INDEX(席位数_三情景!$B$10:$D$10,1,MATCH(假设!$B$4,{"悲观","基准","乐观"},0)) | I13: =IF(G13=0,0,L13/G13) | J13: =H13*假设!$B$7 | K13: =J13*12 | L13: =J13 | M13: =假设!$B$24+假设!$B$25*G13+L13*假设!$B$26+假设!$B$29 | N13: =INDEX(客户支持_三情景!$B$10:$D$10,1,MATCH(假设!$B$4,{"悲观","基准","乐观"},0)) | O13: =L13-M13-N13 | P13: =IF(L13=0,0,O13/L13) | Q13: =INDEX(研发_三情景!$B$10:$D$10,1,MATCH(假设!$B$4,{"悲观","基准","乐观"},0)) | R13: =INDEX(销售市场_三情景!$B$10:$D$10,1,MATCH(假设!$B$4,{"悲观","基准","乐观"},0)) | S13: =INDEX(管理行政_三情景!$B$10:$D$10,1,MATCH(假设!$B$4,{"悲观","基准","乐观"},0)) | T13: =O13-Q13-R13-S13 | U13: =T13-W13-X13 | V13: =假设!$B$33+SUM($U$5:U13)+SUM($Y$5:Y13)-SUM($Z$5:Z13) | W13: =INDEX(营运资本_三情景!$B$10:$D$10,1,MATCH(假设!$B$4,{"悲观","基准","乐观"},0)) | X13: =INDEX(税金_三情景!$B$10:$D$10,1,MATCH(假设!$B$4,{"悲观","基准","乐观"},0)) | Y13: =IF($A13=18,假设!$B$35,0) | Z13: =L13*假设!$B$30
A14: 10 | B14: =INDEX(注册量_三情景!$B$11:$D$11,1,MATCH(假设!$B$4,{"悲观","基准","乐观"},0)) | C14: =B14*INDEX(转化率_三情景!$B$11:$D$11,1,MATCH(假设!$B$4,{"悲观","基准","乐观"},0)) | D14: =INDEX(AE数_三情景!$B$11:$D$11,1,MATCH(假设!$B$4,{"悲观","基准","乐观"},0))*INDEX(AE人效_三情景!$B$11:$D$11,1,MATCH(假设!$B$4,{"悲观","基准","乐观"},0)) | E14: =C14+D14 | F14: =INDEX(流失_三情景!$B$11:$D$11,1,MATCH(假设!$B$4,{"悲观","基准","乐观"},0)) | G14: =INDEX(客户数_三情景!$B$11:$D$11,1,MATCH(假设!$B$4,{"悲观","基准","乐观"},0)) | H14: =INDEX(席位数_三情景!$B$11:$D$11,1,MATCH(假设!$B$4,{"悲观","基准","乐观"},0)) | I14: =IF(G14=0,0,L14/G14) | J14: =H14*假设!$B$7 | K14: =J14*12 | L14: =J14 | M14: =假设!$B$24+假设!$B$25*G14+L14*假设!$B$26+假设!$B$29 | N14: =INDEX(客户支持_三情景!$B$11:$D$11,1,MATCH(假设!$B$4,{"悲观","基准","乐观"},0)) | O14: =L14-M14-N14 | P14: =IF(L14=0,0,O14/L14) | Q14: =INDEX(研发_三情景!$B$11:$D$11,1,MATCH(假设!$B$4,{"悲观","基准","乐观"},0)) | R14: =INDEX(销售市场_三情景!$B$11:$D$11,1,MATCH(假设!$B$4,{"悲观","基准","乐观"},0)) | S14: =INDEX(管理行政_三情景!$B$11:$D$11,1,MATCH(假设!$B$4,{"悲观","基准","乐观"},0)) | T14: =O14-Q14-R14-S14 | U14: =T14-W14-X14 | V14: =假设!$B$33+SUM($U$5:U14)+SUM($Y$5:Y14)-SUM($Z$5:Z14) | W14: =INDEX(营运资本_三情景!$B$11:$D$11,1,MATCH(假设!$B$4,{"悲观","基准","乐观"},0)) | X14: =INDEX(税金_三情景!$B$11:$D$11,1,MATCH(假设!$B$4,{"悲观","基准","乐观"},0)) | Y14: =IF($A14=18,假设!$B$35,0) | Z14: =L14*假设!$B$30
A15: 11 | B15: =INDEX(注册量_三情景!$B$12:$D$12,1,MATCH(假设!$B$4,{"悲观","基准","乐观"},0)) | C15: =B15*INDEX(转化率_三情景!$B$12:$D$12,1,MATCH(假设!$B$4,{"悲观","基准","乐观"},0)) | D15: =INDEX(AE数_三情景!$B$12:$D$12,1,MATCH(假设!$B$4,{"悲观","基准","乐观"},0))*INDEX(AE人效_三情景!$B$12:$D$12,1,MATCH(假设!$B$4,{"悲观","基准","乐观"},0)) | E15: =C15+D15 | F15: =INDEX(流失_三情景!$B$12:$D$12,1,MATCH(假设!$B$4,{"悲观","基准","乐观"},0)) | G15: =INDEX(客户数_三情景!$B$12:$D$12,1,MATCH(假设!$B$4,{"悲观","基准","乐观"},0)) | H15: =INDEX(席位数_三情景!$B$12:$D$12,1,MATCH(假设!$B$4,{"悲观","基准","乐观"},0)) | I15: =IF(G15=0,0,L15/G15) | J15: =H15*假设!$B$7 | K15: =J15*12 | L15: =J15 | M15: =假设!$B$24+假设!$B$25*G15+L15*假设!$B$26+假设!$B$29 | N15: =INDEX(客户支持_三情景!$B$12:$D$12,1,MATCH(假设!$B$4,{"悲观","基准","乐观"},0)) | O15: =L15-M15-N15 | P15: =IF(L15=0,0,O15/L15) | Q15: =INDEX(研发_三情景!$B$12:$D$12,1,MATCH(假设!$B$4,{"悲观","基准","乐观"},0)) | R15: =INDEX(销售市场_三情景!$B$12:$D$12,1,MATCH(假设!$B$4,{"悲观","基准","乐观"},0)) | S15: =INDEX(管理行政_三情景!$B$12:$D$12,1,MATCH(假设!$B$4,{"悲观","基准","乐观"},0)) | T15: =O15-Q15-R15-S15 | U15: =T15-W15-X15 | V15: =假设!$B$33+SUM($U$5:U15)+SUM($Y$5:Y15)-SUM($Z$5:Z15) | W15: =INDEX(营运资本_三情景!$B$12:$D$12,1,MATCH(假设!$B$4,{"悲观","基准","乐观"},0)) | X15: =INDEX(税金_三情景!$B$12:$D$12,1,MATCH(假设!$B$4,{"悲观","基准","乐观"},0)) | Y15: =IF($A15=18,假设!$B$35,0) | Z15: =L15*假设!$B$30
A16: 12 | B16: =INDEX(注册量_三情景!$B$13:$D$13,1,MATCH(假设!$B$4,{"悲观","基准","乐观"},0)) | C16: =B16*INDEX(转化率_三情景!$B$13:$D$13,1,MATCH(假设!$B$4,{"悲观","基准","乐观"},0)) | D16: =INDEX(AE数_三情景!$B$13:$D$13,1,MATCH(假设!$B$4,{"悲观","基准","乐观"},0))*INDEX(AE人效_三情景!$B$13:$D$13,1,MATCH(假设!$B$4,{"悲观","基准","乐观"},0)) | E16: =C16+D16 | F16: =INDEX(流失_三情景!$B$13:$D$13,1,MATCH(假设!$B$4,{"悲观","基准","乐观"},0)) | G16: =INDEX(客户数_三情景!$B$13:$D$13,1,MATCH(假设!$B$4,{"悲观","基准","乐观"},0)) | H16: =INDEX(席位数_三情景!$B$13:$D$13,1,MATCH(假设!$B$4,{"悲观","基准","乐观"},0)) | I16: =IF(G16=0,0,L16/G16) | J16: =H16*假设!$B$7 | K16: =J16*12 | L16: =J16 | M16: =假设!$B$24+假设!$B$25*G16+L16*假设!$B$26+假设!$B$29 | N16: =INDEX(客户支持_三情景!$B$13:$D$13,1,MATCH(假设!$B$4,{"悲观","基准","乐观"},0)) | O16: =L16-M16-N16 | P16: =IF(L16=0,0,O16/L16) | Q16: =INDEX(研发_三情景!$B$13:$D$13,1,MATCH(假设!$B$4,{"悲观","基准","乐观"},0)) | R16: =INDEX(销售市场_三情景!$B$13:$D$13,1,MATCH(假设!$B$4,{"悲观","基准","乐观"},0)) | S16: =INDEX(管理行政_三情景!$B$13:$D$13,1,MATCH(假设!$B$4,{"悲观","基准","乐观"},0)) | T16: =O16-Q16-R16-S16 | U16: =T16-W16-X16 | V16: =假设!$B$33+SUM($U$5:U16)+SUM($Y$5:Y16)-SUM($Z$5:Z16) | W16: =INDEX(营运资本_三情景!$B$13:$D$13,1,MATCH(假设!$B$4,{"悲观","基准","乐观"},0)) | X16: =INDEX(税金_三情景!$B$13:$D$13,1,MATCH(假设!$B$4,{"悲观","基准","乐观"},0)) | Y16: =IF($A16=18,假设!$B$35,0) | Z16: =L16*假设!$B$30
A17: 13 | B17: =INDEX(注册量_三情景!$B$14:$D$14,1,MATCH(假设!$B$4,{"悲观","基准","乐观"},0)) | C17: =B17*INDEX(转化率_三情景!$B$14:$D$14,1,MATCH(假设!$B$4,{"悲观","基准","乐观"},0)) | D17: =INDEX(AE数_三情景!$B$14:$D$14,1,MATCH(假设!$B$4,{"悲观","基准","乐观"},0))*INDEX(AE人效_三情景!$B$14:$D$14,1,MATCH(假设!$B$4,{"悲观","基准","乐观"},0)) | E17: =C17+D17 | F17: =INDEX(流失_三情景!$B$14:$D$14,1,MATCH(假设!$B$4,{"悲观","基准","乐观"},0)) | G17: =INDEX(客户数_三情景!$B$14:$D$14,1,MATCH(假设!$B$4,{"悲观","基准","乐观"},0)) | H17: =INDEX(席位数_三情景!$B$14:$D$14,1,MATCH(假设!$B$4,{"悲观","基准","乐观"},0)) | I17: =IF(G17=0,0,L17/G17) | J17: =H17*假设!$B$7 | K17: =J17*12 | L17: =J17 | M17: =假设!$B$24+假设!$B$25*G17+L17*假设!$B$26+假设!$B$29 | N17: =INDEX(客户支持_三情景!$B$14:$D$14,1,MATCH(假设!$B$4,{"悲观","基准","乐观"},0)) | O17: =L17-M17-N17 | P17: =IF(L17=0,0,O17/L17) | Q17: =INDEX(研发_三情景!$B$14:$D$14,1,MATCH(假设!$B$4,{"悲观","基准","乐观"},0)) | R17: =INDEX(销售市场_三情景!$B$14:$D$14,1,MATCH(假设!$B$4,{"悲观","基准","乐观"},0)) | S17: =INDEX(管理行政_三情景!$B$14:$D$14,1,MATCH(假设!$B$4,{"悲观","基准","乐观"},0)) | T17: =O17-Q17-R17-S17 | U17: =T17-W17-X17 | V17: =假设!$B$33+SUM($U$5:U17)+SUM($Y$5:Y17)-SUM($Z$5:Z17) | W17: =INDEX(营运资本_三情景!$B$14:$D$14,1,MATCH(假设!$B$4,{"悲观","基准","乐观"},0)) | X17: =INDEX(税金_三情景!$B$14:$D$14,1,MATCH(假设!$B$4,{"悲观","基准","乐观"},0)) | Y17: =IF($A17=18,假设!$B$35,0) | Z17: =L17*假设!$B$30
A18: 14 | B18: =INDEX(注册量_三情景!$B$15:$D$15,1,MATCH(假设!$B$4,{"悲观","基准","乐观"},0)) | C18: =B18*INDEX(转化率_三情景!$B$15:$D$15,1,MATCH(假设!$B$4,{"悲观","基准","乐观"},0)) | D18: =INDEX(AE数_三情景!$B$15:$D$15,1,MATCH(假设!$B$4,{"悲观","基准","乐观"},0))*INDEX(AE人效_三情景!$B$15:$D$15,1,MATCH(假设!$B$4,{"悲观","基准","乐观"},0)) | E18: =C18+D18 | F18: =INDEX(流失_三情景!$B$15:$D$15,1,MATCH(假设!$B$4,{"悲观","基准","乐观"},0)) | G18: =INDEX(客户数_三情景!$B$15:$D$15,1,MATCH(假设!$B$4,{"悲观","基准","乐观"},0)) | H18: =INDEX(席位数_三情景!$B$15:$D$15,1,MATCH(假设!$B$4,{"悲观","基准","乐观"},0)) | I18: =IF(G18=0,0,L18/G18) | J18: =H18*假设!$B$7 | K18: =J18*12 | L18: =J18 | M18: =假设!$B$24+假设!$B$25*G18+L18*假设!$B$26+假设!$B$29 | N18: =INDEX(客户支持_三情景!$B$15:$D$15,1,MATCH(假设!$B$4,{"悲观","基准","乐观"},0)) | O18: =L18-M18-N18 | P18: =IF(L18=0,0,O18/L18) | Q18: =INDEX(研发_三情景!$B$15:$D$15,1,MATCH(假设!$B$4,{"悲观","基准","乐观"},0)) | R18: =INDEX(销售市场_三情景!$B$15:$D$15,1,MATCH(假设!$B$4,{"悲观","基准","乐观"},0)) | S18: =INDEX(管理行政_三情景!$B$15:$D$15,1,MATCH(假设!$B$4,{"悲观","基准","乐观"},0)) | T18: =O18-Q18-R18-S18 | U18: =T18-W18-X18 | V18: =假设!$B$33+SUM($U$5:U18)+SUM($Y$5:Y18)-SUM($Z$5:Z18) | W18: =INDEX(营运资本_三情景!$B$15:$D$15,1,MATCH(假设!$B$4,{"悲观","基准","乐观"},0)) | X18: =INDEX(税金_三情景!$B$15:$D$15,1,MATCH(假设!$B$4,{"悲观","基准","乐观"},0)) | Y18: =IF($A18=18,假设!$B$35,0) | Z18: =L18*假设!$B$30
A19: 15 | B19: =INDEX(注册量_三情景!$B$16:$D$16,1,MATCH(假设!$B$4,{"悲观","基准","乐观"},0)) | C19: =B19*INDEX(转化率_三情景!$B$16:$D$16,1,MATCH(假设!$B$4,{"悲观","基准","乐观"},0)) | D19: =INDEX(AE数_三情景!$B$16:$D$16,1,MATCH(假设!$B$4,{"悲观","基准","乐观"},0))*INDEX(AE人效_三情景!$B$16:$D$16,1,MATCH(假设!$B$4,{"悲观","基准","乐观"},0)) | E19: =C19+D19 | F19: =INDEX(流失_三情景!$B$16:$D$16,1,MATCH(假设!$B$4,{"悲观","基准","乐观"},0)) | G19: =INDEX(客户数_三情景!$B$16:$D$16,1,MATCH(假设!$B$4,{"悲观","基准","乐观"},0)) | H19: =INDEX(席位数_三情景!$B$16:$D$16,1,MATCH(假设!$B$4,{"悲观","基准","乐观"},0)) | I19: =IF(G19=0,0,L19/G19) | J19: =H19*假设!$B$7 | K19: =J19*12 | L19: =J19 | M19: =假设!$B$24+假设!$B$25*G19+L19*假设!$B$26+假设!$B$29 | N19: =INDEX(客户支持_三情景!$B$16:$D$16,1,MATCH(假设!$B$4,{"悲观","基准","乐观"},0)) | O19: =L19-M19-N19 | P19: =IF(L19=0,0,O19/L19) | Q19: =INDEX(研发_三情景!$B$16:$D$16,1,MATCH(假设!$B$4,{"悲观","基准","乐观"},0)) | R19: =INDEX(销售市场_三情景!$B$16:$D$16,1,MATCH(假设!$B$4,{"悲观","基准","乐观"},0)) | S19: =INDEX(管理行政_三情景!$B$16:$D$16,1,MATCH(假设!$B$4,{"悲观","基准","乐观"},0)) | T19: =O19-Q19-R19-S19 | U19: =T19-W19-X19 | V19: =假设!$B$33+SUM($U$5:U19)+SUM($Y$5:Y19)-SUM($Z$5:Z19) | W19: =INDEX(营运资本_三情景!$B$16:$D$16,1,MATCH(假设!$B$4,{"悲观","基准","乐观"},0)) | X19: =INDEX(税金_三情景!$B$16:$D$16,1,MATCH(假设!$B$4,{"悲观","基准","乐观"},0)) | Y19: =IF($A19=18,假设!$B$35,0) | Z19: =L19*假设!$B$30
A20: 16 | B20: =INDEX(注册量_三情景!$B$17:$D$17,1,MATCH(假设!$B$4,{"悲观","基准","乐观"},0)) | C20: =B20*INDEX(转化率_三情景!$B$17:$D$17,1,MATCH(假设!$B$4,{"悲观","基准","乐观"},0)) | D20: =INDEX(AE数_三情景!$B$17:$D$17,1,MATCH(假设!$B$4,{"悲观","基准","乐观"},0))*INDEX(AE人效_三情景!$B$17:$D$17,1,MATCH(假设!$B$4,{"悲观","基准","乐观"},0)) | E20: =C20+D20 | F20: =INDEX(流失_三情景!$B$17:$D$17,1,MATCH(假设!$B$4,{"悲观","基准","乐观"},0)) | G20: =INDEX(客户数_三情景!$B$17:$D$17,1,MATCH(假设!$B$4,{"悲观","基准","乐观"},0)) | H20: =INDEX(席位数_三情景!$B$17:$D$17,1,MATCH(假设!$B$4,{"悲观","基准","乐观"},0)) | I20: =IF(G20=0,0,L20/G20) | J20: =H20*假设!$B$7 | K20: =J20*12 | L20: =J20 | M20: =假设!$B$24+假设!$B$25*G20+L20*假设!$B$26+假设!$B$29 | N20: =INDEX(客户支持_三情景!$B$17:$D$17,1,MATCH(假设!$B$4,{"悲观","基准","乐观"},0)) | O20: =L20-M20-N20 | P20: =IF(L20=0,0,O20/L20) | Q20: =INDEX(研发_三情景!$B$17:$D$17,1,MATCH(假设!$B$4,{"悲观","基准","乐观"},0)) | R20: =INDEX(销售市场_三情景!$B$17:$D$17,1,MATCH(假设!$B$4,{"悲观","基准","乐观"},0)) | S20: =INDEX(管理行政_三情景!$B$17:$D$17,1,MATCH(假设!$B$4,{"悲观","基准","乐观"},0)) | T20: =O20-Q20-R20-S20 | U20: =T20-W20-X20 | V20: =假设!$B$33+SUM($U$5:U20)+SUM($Y$5:Y20)-SUM($Z$5:Z20) | W20: =INDEX(营运资本_三情景!$B$17:$D$17,1,MATCH(假设!$B$4,{"悲观","基准","乐观"},0)) | X20: =INDEX(税金_三情景!$B$17:$D$17,1,MATCH(假设!$B$4,{"悲观","基准","乐观"},0)) | Y20: =IF($A20=18,假设!$B$35,0) | Z20: =L20*假设!$B$30
A21: 17 | B21: =INDEX(注册量_三情景!$B$18:$D$18,1,MATCH(假设!$B$4,{"悲观","基准","乐观"},0)) | C21: =B21*INDEX(转化率_三情景!$B$18:$D$18,1,MATCH(假设!$B$4,{"悲观","基准","乐观"},0)) | D21: =INDEX(AE数_三情景!$B$18:$D$18,1,MATCH(假设!$B$4,{"悲观","基准","乐观"},0))*INDEX(AE人效_三情景!$B$18:$D$18,1,MATCH(假设!$B$4,{"悲观","基准","乐观"},0)) | E21: =C21+D21 | F21: =INDEX(流失_三情景!$B$18:$D$18,1,MATCH(假设!$B$4,{"悲观","基准","乐观"},0)) | G21: =INDEX(客户数_三情景!$B$18:$D$18,1,MATCH(假设!$B$4,{"悲观","基准","乐观"},0)) | H21: =INDEX(席位数_三情景!$B$18:$D$18,1,MATCH(假设!$B$4,{"悲观","基准","乐观"},0)) | I21: =IF(G21=0,0,L21/G21) | J21: =H21*假设!$B$7 | K21: =J21*12 | L21: =J21 | M21: =假设!$B$24+假设!$B$25*G21+L21*假设!$B$26+假设!$B$29 | N21: =INDEX(客户支持_三情景!$B$18:$D$18,1,MATCH(假设!$B$4,{"悲观","基准","乐观"},0)) | O21: =L21-M21-N21 | P21: =IF(L21=0,0,O21/L21) | Q21: =INDEX(研发_三情景!$B$18:$D$18,1,MATCH(假设!$B$4,{"悲观","基准","乐观"},0)) | R21: =INDEX(销售市场_三情景!$B$18:$D$18,1,MATCH(假设!$B$4,{"悲观","基准","乐观"},0)) | S21: =INDEX(管理行政_三情景!$B$18:$D$18,1,MATCH(假设!$B$4,{"悲观","基准","乐观"},0)) | T21: =O21-Q21-R21-S21 | U21: =T21-W21-X21 | V21: =假设!$B$33+SUM($U$5:U21)+SUM($Y$5:Y21)-SUM($Z$5:Z21) | W21: =INDEX(营运资本_三情景!$B$18:$D$18,1,MATCH(假设!$B$4,{"悲观","基准","乐观"},0)) | X21: =INDEX(税金_三情景!$B$18:$D$18,1,MATCH(假设!$B$4,{"悲观","基准","乐观"},0)) | Y21: =IF($A21=18,假设!$B$35,0) | Z21: =L21*假设!$B$30
A22: 18 | B22: =INDEX(注册量_三情景!$B$19:$D$19,1,MATCH(假设!$B$4,{"悲观","基准","乐观"},0)) | C22: =B22*INDEX(转化率_三情景!$B$19:$D$19,1,MATCH(假设!$B$4,{"悲观","基准","乐观"},0)) | D22: =INDEX(AE数_三情景!$B$19:$D$19,1,MATCH(假设!$B$4,{"悲观","基准","乐观"},0))*INDEX(AE人效_三情景!$B$19:$D$19,1,MATCH(假设!$B$4,{"悲观","基准","乐观"},0)) | E22: =C22+D22 | F22: =INDEX(流失_三情景!$B$19:$D$19,1,MATCH(假设!$B$4,{"悲观","基准","乐观"},0)) | G22: =INDEX(客户数_三情景!$B$19:$D$19,1,MATCH(假设!$B$4,{"悲观","基准","乐观"},0)) | H22: =INDEX(席位数_三情景!$B$19:$D$19,1,MATCH(假设!$B$4,{"悲观","基准","乐观"},0)) | I22: =IF(G22=0,0,L22/G22) | J22: =H22*假设!$B$7 | K22: =J22*12 | L22: =J22 | M22: =假设!$B$24+假设!$B$25*G22+L22*假设!$B$26+假设!$B$29 | N22: =INDEX(客户支持_三情景!$B$19:$D$19,1,MATCH(假设!$B$4,{"悲观","基准","乐观"},0)) | O22: =L22-M22-N22 | P22: =IF(L22=0,0,O22/L22) | Q22: =INDEX(研发_三情景!$B$19:$D$19,1,MATCH(假设!$B$4,{"悲观","基准","乐观"},0)) | R22: =INDEX(销售市场_三情景!$B$19:$D$19,1,MATCH(假设!$B$4,{"悲观","基准","乐观"},0)) | S22: =INDEX(管理行政_三情景!$B$19:$D$19,1,MATCH(假设!$B$4,{"悲观","基准","乐观"},0)) | T22: =O22-Q22-R22-S22 | U22: =T22-W22-X22 | V22: =假设!$B$33+SUM($U$5:U22)+SUM($Y$5:Y22)-SUM($Z$5:Z22) | W22: =INDEX(营运资本_三情景!$B$19:$D$19,1,MATCH(假设!$B$4,{"悲观","基准","乐观"},0)) | X22: =INDEX(税金_三情景!$B$19:$D$19,1,MATCH(假设!$B$4,{"悲观","基准","乐观"},0)) | Y22: =IF($A22=18,假设!$B$35,0) | Z22: =L22*假设!$B$30
A23: 19 | B23: =INDEX(注册量_三情景!$B$20:$D$20,1,MATCH(假设!$B$4,{"悲观","基准","乐观"},0)) | C23: =B23*INDEX(转化率_三情景!$B$20:$D$20,1,MATCH(假设!$B$4,{"悲观","基准","乐观"},0)) | D23: =INDEX(AE数_三情景!$B$20:$D$20,1,MATCH(假设!$B$4,{"悲观","基准","乐观"},0))*INDEX(AE人效_三情景!$B$20:$D$20,1,MATCH(假设!$B$4,{"悲观","基准","乐观"},0)) | E23: =C23+D23 | F23: =INDEX(流失_三情景!$B$20:$D$20,1,MATCH(假设!$B$4,{"悲观","基准","乐观"},0)) | G23: =INDEX(客户数_三情景!$B$20:$D$20,1,MATCH(假设!$B$4,{"悲观","基准","乐观"},0)) | H23: =INDEX(席位数_三情景!$B$20:$D$20,1,MATCH(假设!$B$4,{"悲观","基准","乐观"},0)) | I23: =IF(G23=0,0,L23/G23) | J23: =H23*假设!$B$7 | K23: =J23*12 | L23: =J23 | M23: =假设!$B$24+假设!$B$25*G23+L23*假设!$B$26+假设!$B$29 | N23: =INDEX(客户支持_三情景!$B$20:$D$20,1,MATCH(假设!$B$4,{"悲观","基准","乐观"},0)) | O23: =L23-M23-N23 | P23: =IF(L23=0,0,O23/L23) | Q23: =INDEX(研发_三情景!$B$20:$D$20,1,MATCH(假设!$B$4,{"悲观","基准","乐观"},0)) | R23: =INDEX(销售市场_三情景!$B$20:$D$20,1,MATCH(假设!$B$4,{"悲观","基准","乐观"},0)) | S23: =INDEX(管理行政_三情景!$B$20:$D$20,1,MATCH(假设!$B$4,{"悲观","基准","乐观"},0)) | T23: =O23-Q23-R23-S23 | U23: =T23-W23-X23 | V23: =假设!$B$33+SUM($U$5:U23)+SUM($Y$5:Y23)-SUM($Z$5:Z23) | W23: =INDEX(营运资本_三情景!$B$20:$D$20,1,MATCH(假设!$B$4,{"悲观","基准","乐观"},0)) | X23: =INDEX(税金_三情景!$B$20:$D$20,1,MATCH(假设!$B$4,{"悲观","基准","乐观"},0)) | Y23: =IF($A23=18,假设!$B$35,0) | Z23: =L23*假设!$B$30
A24: 20 | B24: =INDEX(注册量_三情景!$B$21:$D$21,1,MATCH(假设!$B$4,{"悲观","基准","乐观"},0)) | C24: =B24*INDEX(转化率_三情景!$B$21:$D$21,1,MATCH(假设!$B$4,{"悲观","基准","乐观"},0)) | D24: =INDEX(AE数_三情景!$B$21:$D$21,1,MATCH(假设!$B$4,{"悲观","基准","乐观"},0))*INDEX(AE人效_三情景!$B$21:$D$21,1,MATCH(假设!$B$4,{"悲观","基准","乐观"},0)) | E24: =C24+D24 | F24: =INDEX(流失_三情景!$B$21:$D$21,1,MATCH(假设!$B$4,{"悲观","基准","乐观"},0)) | G24: =INDEX(客户数_三情景!$B$21:$D$21,1,MATCH(假设!$B$4,{"悲观","基准","乐观"},0)) | H24: =INDEX(席位数_三情景!$B$21:$D$21,1,MATCH(假设!$B$4,{"悲观","基准","乐观"},0)) | I24: =IF(G24=0,0,L24/G24) | J24: =H24*假设!$B$7 | K24: =J24*12 | L24: =J24 | M24: =假设!$B$24+假设!$B$25*G24+L24*假设!$B$26+假设!$B$29 | N24: =INDEX(客户支持_三情景!$B$21:$D$21,1,MATCH(假设!$B$4,{"悲观","基准","乐观"},0)) | O24: =L24-M24-N24 | P24: =IF(L24=0,0,O24/L24) | Q24: =INDEX(研发_三情景!$B$21:$D$21,1,MATCH(假设!$B$4,{"悲观","基准","乐观"},0)) | R24: =INDEX(销售市场_三情景!$B$21:$D$21,1,MATCH(假设!$B$4,{"悲观","基准","乐观"},0)) | S24: =INDEX(管理行政_三情景!$B$21:$D$21,1,MATCH(假设!$B$4,{"悲观","基准","乐观"},0)) | T24: =O24-Q24-R24-S24 | U24: =T24-W24-X24 | V24: =假设!$B$33+SUM($U$5:U24)+SUM($Y$5:Y24)-SUM($Z$5:Z24) | W24: =INDEX(营运资本_三情景!$B$21:$D$21,1,MATCH(假设!$B$4,{"悲观","基准","乐观"},0)) | X24: =INDEX(税金_三情景!$B$21:$D$21,1,MATCH(假设!$B$4,{"悲观","基准","乐观"},0)) | Y24: =IF($A24=18,假设!$B$35,0) | Z24: =L24*假设!$B$30
A25: 21 | B25: =INDEX(注册量_三情景!$B$22:$D$22,1,MATCH(假设!$B$4,{"悲观","基准","乐观"},0)) | C25: =B25*INDEX(转化率_三情景!$B$22:$D$22,1,MATCH(假设!$B$4,{"悲观","基准","乐观"},0)) | D25: =INDEX(AE数_三情景!$B$22:$D$22,1,MATCH(假设!$B$4,{"悲观","基准","乐观"},0))*INDEX(AE人效_三情景!$B$22:$D$22,1,MATCH(假设!$B$4,{"悲观","基准","乐观"},0)) | E25: =C25+D25 | F25: =INDEX(流失_三情景!$B$22:$D$22,1,MATCH(假设!$B$4,{"悲观","基准","乐观"},0)) | G25: =INDEX(客户数_三情景!$B$22:$D$22,1,MATCH(假设!$B$4,{"悲观","基准","乐观"},0)) | H25: =INDEX(席位数_三情景!$B$22:$D$22,1,MATCH(假设!$B$4,{"悲观","基准","乐观"},0)) | I25: =IF(G25=0,0,L25/G25) | J25: =H25*假设!$B$7 | K25: =J25*12 | L25: =J25 | M25: =假设!$B$24+假设!$B$25*G25+L25*假设!$B$26+假设!$B$29 | N25: =INDEX(客户支持_三情景!$B$22:$D$22,1,MATCH(假设!$B$4,{"悲观","基准","乐观"},0)) | O25: =L25-M25-N25 | P25: =IF(L25=0,0,O25/L25) | Q25: =INDEX(研发_三情景!$B$22:$D$22,1,MATCH(假设!$B$4,{"悲观","基准","乐观"},0)) | R25: =INDEX(销售市场_三情景!$B$22:$D$22,1,MATCH(假设!$B$4,{"悲观","基准","乐观"},0)) | S25: =INDEX(管理行政_三情景!$B$22:$D$22,1,MATCH(假设!$B$4,{"悲观","基准","乐观"},0)) | T25: =O25-Q25-R25-S25 | U25: =T25-W25-X25 | V25: =假设!$B$33+SUM($U$5:U25)+SUM($Y$5:Y25)-SUM($Z$5:Z25) | W25: =INDEX(营运资本_三情景!$B$22:$D$22,1,MATCH(假设!$B$4,{"悲观","基准","乐观"},0)) | X25: =INDEX(税金_三情景!$B$22:$D$22,1,MATCH(假设!$B$4,{"悲观","基准","乐观"},0)) | Y25: =IF($A25=18,假设!$B$35,0) | Z25: =L25*假设!$B$30
A26: 22 | B26: =INDEX(注册量_三情景!$B$23:$D$23,1,MATCH(假设!$B$4,{"悲观","基准","乐观"},0)) | C26: =B26*INDEX(转化率_三情景!$B$23:$D$23,1,MATCH(假设!$B$4,{"悲观","基准","乐观"},0)) | D26: =INDEX(AE数_三情景!$B$23:$D$23,1,MATCH(假设!$B$4,{"悲观","基准","乐观"},0))*INDEX(AE人效_三情景!$B$23:$D$23,1,MATCH(假设!$B$4,{"悲观","基准","乐观"},0)) | E26: =C26+D26 | F26: =INDEX(流失_三情景!$B$23:$D$23,1,MATCH(假设!$B$4,{"悲观","基准","乐观"},0)) | G26: =INDEX(客户数_三情景!$B$23:$D$23,1,MATCH(假设!$B$4,{"悲观","基准","乐观"},0)) | H26: =INDEX(席位数_三情景!$B$23:$D$23,1,MATCH(假设!$B$4,{"悲观","基准","乐观"},0)) | I26: =IF(G26=0,0,L26/G26) | J26: =H26*假设!$B$7 | K26: =J26*12 | L26: =J26 | M26: =假设!$B$24+假设!$B$25*G26+L26*假设!$B$26+假设!$B$29 | N26: =INDEX(客户支持_三情景!$B$23:$D$23,1,MATCH(假设!$B$4,{"悲观","基准","乐观"},0)) | O26: =L26-M26-N26 | P26: =IF(L26=0,0,O26/L26) | Q26: =INDEX(研发_三情景!$B$23:$D$23,1,MATCH(假设!$B$4,{"悲观","基准","乐观"},0)) | R26: =INDEX(销售市场_三情景!$B$23:$D$23,1,MATCH(假设!$B$4,{"悲观","基准","乐观"},0)) | S26: =INDEX(管理行政_三情景!$B$23:$D$23,1,MATCH(假设!$B$4,{"悲观","基准","乐观"},0)) | T26: =O26-Q26-R26-S26 | U26: =T26-W26-X26 | V26: =假设!$B$33+SUM($U$5:U26)+SUM($Y$5:Y26)-SUM($Z$5:Z26) | W26: =INDEX(营运资本_三情景!$B$23:$D$23,1,MATCH(假设!$B$4,{"悲观","基准","乐观"},0)) | X26: =INDEX(税金_三情景!$B$23:$D$23,1,MATCH(假设!$B$4,{"悲观","基准","乐观"},0)) | Y26: =IF($A26=18,假设!$B$35,0) | Z26: =L26*假设!$B$30
A27: 23 | B27: =INDEX(注册量_三情景!$B$24:$D$24,1,MATCH(假设!$B$4,{"悲观","基准","乐观"},0)) | C27: =B27*INDEX(转化率_三情景!$B$24:$D$24,1,MATCH(假设!$B$4,{"悲观","基准","乐观"},0)) | D27: =INDEX(AE数_三情景!$B$24:$D$24,1,MATCH(假设!$B$4,{"悲观","基准","乐观"},0))*INDEX(AE人效_三情景!$B$24:$D$24,1,MATCH(假设!$B$4,{"悲观","基准","乐观"},0)) | E27: =C27+D27 | F27: =INDEX(流失_三情景!$B$24:$D$24,1,MATCH(假设!$B$4,{"悲观","基准","乐观"},0)) | G27: =INDEX(客户数_三情景!$B$24:$D$24,1,MATCH(假设!$B$4,{"悲观","基准","乐观"},0)) | H27: =INDEX(席位数_三情景!$B$24:$D$24,1,MATCH(假设!$B$4,{"悲观","基准","乐观"},0)) | I27: =IF(G27=0,0,L27/G27) | J27: =H27*假设!$B$7 | K27: =J27*12 | L27: =J27 | M27: =假设!$B$24+假设!$B$25*G27+L27*假设!$B$26+假设!$B$29 | N27: =INDEX(客户支持_三情景!$B$24:$D$24,1,MATCH(假设!$B$4,{"悲观","基准","乐观"},0)) | O27: =L27-M27-N27 | P27: =IF(L27=0,0,O27/L27) | Q27: =INDEX(研发_三情景!$B$24:$D$24,1,MATCH(假设!$B$4,{"悲观","基准","乐观"},0)) | R27: =INDEX(销售市场_三情景!$B$24:$D$24,1,MATCH(假设!$B$4,{"悲观","基准","乐观"},0)) | S27: =INDEX(管理行政_三情景!$B$24:$D$24,1,MATCH(假设!$B$4,{"悲观","基准","乐观"},0)) | T27: =O27-Q27-R27-S27 | U27: =T27-W27-X27 | V27: =假设!$B$33+SUM($U$5:U27)+SUM($Y$5:Y27)-SUM($Z$5:Z27) | W27: =INDEX(营运资本_三情景!$B$24:$D$24,1,MATCH(假设!$B$4,{"悲观","基准","乐观"},0)) | X27: =INDEX(税金_三情景!$B$24:$D$24,1,MATCH(假设!$B$4,{"悲观","基准","乐观"},0)) | Y27: =IF($A27=18,假设!$B$35,0) | Z27: =L27*假设!$B$30
A28: 24 | B28: =INDEX(注册量_三情景!$B$25:$D$25,1,MATCH(假设!$B$4,{"悲观","基准","乐观"},0)) | C28: =B28*INDEX(转化率_三情景!$B$25:$D$25,1,MATCH(假设!$B$4,{"悲观","基准","乐观"},0)) | D28: =INDEX(AE数_三情景!$B$25:$D$25,1,MATCH(假设!$B$4,{"悲观","基准","乐观"},0))*INDEX(AE人效_三情景!$B$25:$D$25,1,MATCH(假设!$B$4,{"悲观","基准","乐观"},0)) | E28: =C28+D28 | F28: =INDEX(流失_三情景!$B$25:$D$25,1,MATCH(假设!$B$4,{"悲观","基准","乐观"},0)) | G28: =INDEX(客户数_三情景!$B$25:$D$25,1,MATCH(假设!$B$4,{"悲观","基准","乐观"},0)) | H28: =INDEX(席位数_三情景!$B$25:$D$25,1,MATCH(假设!$B$4,{"悲观","基准","乐观"},0)) | I28: =IF(G28=0,0,L28/G28) | J28: =H28*假设!$B$7 | K28: =J28*12 | L28: =J28 | M28: =假设!$B$24+假设!$B$25*G28+L28*假设!$B$26+假设!$B$29 | N28: =INDEX(客户支持_三情景!$B$25:$D$25,1,MATCH(假设!$B$4,{"悲观","基准","乐观"},0)) | O28: =L28-M28-N28 | P28: =IF(L28=0,0,O28/L28) | Q28: =INDEX(研发_三情景!$B$25:$D$25,1,MATCH(假设!$B$4,{"悲观","基准","乐观"},0)) | R28: =INDEX(销售市场_三情景!$B$25:$D$25,1,MATCH(假设!$B$4,{"悲观","基准","乐观"},0)) | S28: =INDEX(管理行政_三情景!$B$25:$D$25,1,MATCH(假设!$B$4,{"悲观","基准","乐观"},0)) | T28: =O28-Q28-R28-S28 | U28: =T28-W28-X28 | V28: =假设!$B$33+SUM($U$5:U28)+SUM($Y$5:Y28)-SUM($Z$5:Z28) | W28: =INDEX(营运资本_三情景!$B$25:$D$25,1,MATCH(假设!$B$4,{"悲观","基准","乐观"},0)) | X28: =INDEX(税金_三情景!$B$25:$D$25,1,MATCH(假设!$B$4,{"悲观","基准","乐观"},0)) | Y28: =IF($A28=18,假设!$B$35,0) | Z28: =L28*假设!$B$30
A29: 25 | B29: =INDEX(注册量_三情景!$B$26:$D$26,1,MATCH(假设!$B$4,{"悲观","基准","乐观"},0)) | C29: =B29*INDEX(转化率_三情景!$B$26:$D$26,1,MATCH(假设!$B$4,{"悲观","基准","乐观"},0)) | D29: =INDEX(AE数_三情景!$B$26:$D$26,1,MATCH(假设!$B$4,{"悲观","基准","乐观"},0))*INDEX(AE人效_三情景!$B$26:$D$26,1,MATCH(假设!$B$4,{"悲观","基准","乐观"},0)) | E29: =C29+D29 | F29: =INDEX(流失_三情景!$B$26:$D$26,1,MATCH(假设!$B$4,{"悲观","基准","乐观"},0)) | G29: =INDEX(客户数_三情景!$B$26:$D$26,1,MATCH(假设!$B$4,{"悲观","基准","乐观"},0)) | H29: =INDEX(席位数_三情景!$B$26:$D$26,1,MATCH(假设!$B$4,{"悲观","基准","乐观"},0)) | I29: =IF(G29=0,0,L29/G29) | J29: =H29*假设!$B$7 | K29: =J29*12 | L29: =J29 | M29: =假设!$B$24+假设!$B$25*G29+L29*假设!$B$26+假设!$B$29 | N29: =INDEX(客户支持_三情景!$B$26:$D$26,1,MATCH(假设!$B$4,{"悲观","基准","乐观"},0)) | O29: =L29-M29-N29 | P29: =IF(L29=0,0,O29/L29) | Q29: =INDEX(研发_三情景!$B$26:$D$26,1,MATCH(假设!$B$4,{"悲观","基准","乐观"},0)) | R29: =INDEX(销售市场_三情景!$B$26:$D$26,1,MATCH(假设!$B$4,{"悲观","基准","乐观"},0)) | S29: =INDEX(管理行政_三情景!$B$26:$D$26,1,MATCH(假设!$B$4,{"悲观","基准","乐观"},0)) | T29: =O29-Q29-R29-S29 | U29: =T29-W29-X29 | V29: =假设!$B$33+SUM($U$5:U29)+SUM($Y$5:Y29)-SUM($Z$5:Z29) | W29: =INDEX(营运资本_三情景!$B$26:$D$26,1,MATCH(假设!$B$4,{"悲观","基准","乐观"},0)) | X29: =INDEX(税金_三情景!$B$26:$D$26,1,MATCH(假设!$B$4,{"悲观","基准","乐观"},0)) | Y29: =IF($A29=18,假设!$B$35,0) | Z29: =L29*假设!$B$30
A30: 26 | B30: =INDEX(注册量_三情景!$B$27:$D$27,1,MATCH(假设!$B$4,{"悲观","基准","乐观"},0)) | C30: =B30*INDEX(转化率_三情景!$B$27:$D$27,1,MATCH(假设!$B$4,{"悲观","基准","乐观"},0)) | D30: =INDEX(AE数_三情景!$B$27:$D$27,1,MATCH(假设!$B$4,{"悲观","基准","乐观"},0))*INDEX(AE人效_三情景!$B$27:$D$27,1,MATCH(假设!$B$4,{"悲观","基准","乐观"},0)) | E30: =C30+D30 | F30: =INDEX(流失_三情景!$B$27:$D$27,1,MATCH(假设!$B$4,{"悲观","基准","乐观"},0)) | G30: =INDEX(客户数_三情景!$B$27:$D$27,1,MATCH(假设!$B$4,{"悲观","基准","乐观"},0)) | H30: =INDEX(席位数_三情景!$B$27:$D$27,1,MATCH(假设!$B$4,{"悲观","基准","乐观"},0)) | I30: =IF(G30=0,0,L30/G30) | J30: =H30*假设!$B$7 | K30: =J30*12 | L30: =J30 | M30: =假设!$B$24+假设!$B$25*G30+L30*假设!$B$26+假设!$B$29 | N30: =INDEX(客户支持_三情景!$B$27:$D$27,1,MATCH(假设!$B$4,{"悲观","基准","乐观"},0)) | O30: =L30-M30-N30 | P30: =IF(L30=0,0,O30/L30) | Q30: =INDEX(研发_三情景!$B$27:$D$27,1,MATCH(假设!$B$4,{"悲观","基准","乐观"},0)) | R30: =INDEX(销售市场_三情景!$B$27:$D$27,1,MATCH(假设!$B$4,{"悲观","基准","乐观"},0)) | S30: =INDEX(管理行政_三情景!$B$27:$D$27,1,MATCH(假设!$B$4,{"悲观","基准","乐观"},0)) | T30: =O30-Q30-R30-S30 | U30: =T30-W30-X30 | V30: =假设!$B$33+SUM($U$5:U30)+SUM($Y$5:Y30)-SUM($Z$5:Z30) | W30: =INDEX(营运资本_三情景!$B$27:$D$27,1,MATCH(假设!$B$4,{"悲观","基准","乐观"},0)) | X30: =INDEX(税金_三情景!$B$27:$D$27,1,MATCH(假设!$B$4,{"悲观","基准","乐观"},0)) | Y30: =IF($A30=18,假设!$B$35,0) | Z30: =L30*假设!$B$30
A31: 27 | B31: =INDEX(注册量_三情景!$B$28:$D$28,1,MATCH(假设!$B$4,{"悲观","基准","乐观"},0)) | C31: =B31*INDEX(转化率_三情景!$B$28:$D$28,1,MATCH(假设!$B$4,{"悲观","基准","乐观"},0)) | D31: =INDEX(AE数_三情景!$B$28:$D$28,1,MATCH(假设!$B$4,{"悲观","基准","乐观"},0))*INDEX(AE人效_三情景!$B$28:$D$28,1,MATCH(假设!$B$4,{"悲观","基准","乐观"},0)) | E31: =C31+D31 | F31: =INDEX(流失_三情景!$B$28:$D$28,1,MATCH(假设!$B$4,{"悲观","基准","乐观"},0)) | G31: =INDEX(客户数_三情景!$B$28:$D$28,1,MATCH(假设!$B$4,{"悲观","基准","乐观"},0)) | H31: =INDEX(席位数_三情景!$B$28:$D$28,1,MATCH(假设!$B$4,{"悲观","基准","乐观"},0)) | I31: =IF(G31=0,0,L31/G31) | J31: =H31*假设!$B$7 | K31: =J31*12 | L31: =J31 | M31: =假设!$B$24+假设!$B$25*G31+L31*假设!$B$26+假设!$B$29 | N31: =INDEX(客户支持_三情景!$B$28:$D$28,1,MATCH(假设!$B$4,{"悲观","基准","乐观"},0)) | O31: =L31-M31-N31 | P31: =IF(L31=0,0,O31/L31) | Q31: =INDEX(研发_三情景!$B$28:$D$28,1,MATCH(假设!$B$4,{"悲观","基准","乐观"},0)) | R31: =INDEX(销售市场_三情景!$B$28:$D$28,1,MATCH(假设!$B$4,{"悲观","基准","乐观"},0)) | S31: =INDEX(管理行政_三情景!$B$28:$D$28,1,MATCH(假设!$B$4,{"悲观","基准","乐观"},0)) | T31: =O31-Q31-R31-S31 | U31: =T31-W31-X31 | V31: =假设!$B$33+SUM($U$5:U31)+SUM($Y$5:Y31)-SUM($Z$5:Z31) | W31: =INDEX(营运资本_三情景!$B$28:$D$28,1,MATCH(假设!$B$4,{"悲观","基准","乐观"},0)) | X31: =INDEX(税金_三情景!$B$28:$D$28,1,MATCH(假设!$B$4,{"悲观","基准","乐观"},0)) | Y31: =IF($A31=18,假设!$B$35,0) | Z31: =L31*假设!$B$30
A32: 28 | B32: =INDEX(注册量_三情景!$B$29:$D$29,1,MATCH(假设!$B$4,{"悲观","基准","乐观"},0)) | C32: =B32*INDEX(转化率_三情景!$B$29:$D$29,1,MATCH(假设!$B$4,{"悲观","基准","乐观"},0)) | D32: =INDEX(AE数_三情景!$B$29:$D$29,1,MATCH(假设!$B$4,{"悲观","基准","乐观"},0))*INDEX(AE人效_三情景!$B$29:$D$29,1,MATCH(假设!$B$4,{"悲观","基准","乐观"},0)) | E32: =C32+D32 | F32: =INDEX(流失_三情景!$B$29:$D$29,1,MATCH(假设!$B$4,{"悲观","基准","乐观"},0)) | G32: =INDEX(客户数_三情景!$B$29:$D$29,1,MATCH(假设!$B$4,{"悲观","基准","乐观"},0)) | H32: =INDEX(席位数_三情景!$B$29:$D$29,1,MATCH(假设!$B$4,{"悲观","基准","乐观"},0)) | I32: =IF(G32=0,0,L32/G32) | J32: =H32*假设!$B$7 | K32: =J32*12 | L32: =J32 | M32: =假设!$B$24+假设!$B$25*G32+L32*假设!$B$26+假设!$B$29 | N32: =INDEX(客户支持_三情景!$B$29:$D$29,1,MATCH(假设!$B$4,{"悲观","基准","乐观"},0)) | O32: =L32-M32-N32 | P32: =IF(L32=0,0,O32/L32) | Q32: =INDEX(研发_三情景!$B$29:$D$29,1,MATCH(假设!$B$4,{"悲观","基准","乐观"},0)) | R32: =INDEX(销售市场_三情景!$B$29:$D$29,1,MATCH(假设!$B$4,{"悲观","基准","乐观"},0)) | S32: =INDEX(管理行政_三情景!$B$29:$D$29,1,MATCH(假设!$B$4,{"悲观","基准","乐观"},0)) | T32: =O32-Q32-R32-S32 | U32: =T32-W32-X32 | V32: =假设!$B$33+SUM($U$5:U32)+SUM($Y$5:Y32)-SUM($Z$5:Z32) | W32: =INDEX(营运资本_三情景!$B$29:$D$29,1,MATCH(假设!$B$4,{"悲观","基准","乐观"},0)) | X32: =INDEX(税金_三情景!$B$29:$D$29,1,MATCH(假设!$B$4,{"悲观","基准","乐观"},0)) | Y32: =IF($A32=18,假设!$B$35,0) | Z32: =L32*假设!$B$30
A33: 29 | B33: =INDEX(注册量_三情景!$B$30:$D$30,1,MATCH(假设!$B$4,{"悲观","基准","乐观"},0)) | C33: =B33*INDEX(转化率_三情景!$B$30:$D$30,1,MATCH(假设!$B$4,{"悲观","基准","乐观"},0)) | D33: =INDEX(AE数_三情景!$B$30:$D$30,1,MATCH(假设!$B$4,{"悲观","基准","乐观"},0))*INDEX(AE人效_三情景!$B$30:$D$30,1,MATCH(假设!$B$4,{"悲观","基准","乐观"},0)) | E33: =C33+D33 | F33: =INDEX(流失_三情景!$B$30:$D$30,1,MATCH(假设!$B$4,{"悲观","基准","乐观"},0)) | G33: =INDEX(客户数_三情景!$B$30:$D$30,1,MATCH(假设!$B$4,{"悲观","基准","乐观"},0)) | H33: =INDEX(席位数_三情景!$B$30:$D$30,1,MATCH(假设!$B$4,{"悲观","基准","乐观"},0)) | I33: =IF(G33=0,0,L33/G33) | J33: =H33*假设!$B$7 | K33: =J33*12 | L33: =J33 | M33: =假设!$B$24+假设!$B$25*G33+L33*假设!$B$26+假设!$B$29 | N33: =INDEX(客户支持_三情景!$B$30:$D$30,1,MATCH(假设!$B$4,{"悲观","基准","乐观"},0)) | O33: =L33-M33-N33 | P33: =IF(L33=0,0,O33/L33) | Q33: =INDEX(研发_三情景!$B$30:$D$30,1,MATCH(假设!$B$4,{"悲观","基准","乐观"},0)) | R33: =INDEX(销售市场_三情景!$B$30:$D$30,1,MATCH(假设!$B$4,{"悲观","基准","乐观"},0)) | S33: =INDEX(管理行政_三情景!$B$30:$D$30,1,MATCH(假设!$B$4,{"悲观","基准","乐观"},0)) | T33: =O33-Q33-R33-S33 | U33: =T33-W33-X33 | V33: =假设!$B$33+SUM($U$5:U33)+SUM($Y$5:Y33)-SUM($Z$5:Z33) | W33: =INDEX(营运资本_三情景!$B$30:$D$30,1,MATCH(假设!$B$4,{"悲观","基准","乐观"},0)) | X33: =INDEX(税金_三情景!$B$30:$D$30,1,MATCH(假设!$B$4,{"悲观","基准","乐观"},0)) | Y33: =IF($A33=18,假设!$B$35,0) | Z33: =L33*假设!$B$30
A34: 30 | B34: =INDEX(注册量_三情景!$B$31:$D$31,1,MATCH(假设!$B$4,{"悲观","基准","乐观"},0)) | C34: =B34*INDEX(转化率_三情景!$B$31:$D$31,1,MATCH(假设!$B$4,{"悲观","基准","乐观"},0)) | D34: =INDEX(AE数_三情景!$B$31:$D$31,1,MATCH(假设!$B$4,{"悲观","基准","乐观"},0))*INDEX(AE人效_三情景!$B$31:$D$31,1,MATCH(假设!$B$4,{"悲观","基准","乐观"},0)) | E34: =C34+D34 | F34: =INDEX(流失_三情景!$B$31:$D$31,1,MATCH(假设!$B$4,{"悲观","基准","乐观"},0)) | G34: =INDEX(客户数_三情景!$B$31:$D$31,1,MATCH(假设!$B$4,{"悲观","基准","乐观"},0)) | H34: =INDEX(席位数_三情景!$B$31:$D$31,1,MATCH(假设!$B$4,{"悲观","基准","乐观"},0)) | I34: =IF(G34=0,0,L34/G34) | J34: =H34*假设!$B$7 | K34: =J34*12 | L34: =J34 | M34: =假设!$B$24+假设!$B$25*G34+L34*假设!$B$26+假设!$B$29 | N34: =INDEX(客户支持_三情景!$B$31:$D$31,1,MATCH(假设!$B$4,{"悲观","基准","乐观"},0)) | O34: =L34-M34-N34 | P34: =IF(L34=0,0,O34/L34) | Q34: =INDEX(研发_三情景!$B$31:$D$31,1,MATCH(假设!$B$4,{"悲观","基准","乐观"},0)) | R34: =INDEX(销售市场_三情景!$B$31:$D$31,1,MATCH(假设!$B$4,{"悲观","基准","乐观"},0)) | S34: =INDEX(管理行政_三情景!$B$31:$D$31,1,MATCH(假设!$B$4,{"悲观","基准","乐观"},0)) | T34: =O34-Q34-R34-S34 | U34: =T34-W34-X34 | V34: =假设!$B$33+SUM($U$5:U34)+SUM($Y$5:Y34)-SUM($Z$5:Z34) | W34: =INDEX(营运资本_三情景!$B$31:$D$31,1,MATCH(假设!$B$4,{"悲观","基准","乐观"},0)) | X34: =INDEX(税金_三情景!$B$31:$D$31,1,MATCH(假设!$B$4,{"悲观","基准","乐观"},0)) | Y34: =IF($A34=18,假设!$B$35,0) | Z34: =L34*假设!$B$30
A35: 31 | B35: =INDEX(注册量_三情景!$B$32:$D$32,1,MATCH(假设!$B$4,{"悲观","基准","乐观"},0)) | C35: =B35*INDEX(转化率_三情景!$B$32:$D$32,1,MATCH(假设!$B$4,{"悲观","基准","乐观"},0)) | D35: =INDEX(AE数_三情景!$B$32:$D$32,1,MATCH(假设!$B$4,{"悲观","基准","乐观"},0))*INDEX(AE人效_三情景!$B$32:$D$32,1,MATCH(假设!$B$4,{"悲观","基准","乐观"},0)) | E35: =C35+D35 | F35: =INDEX(流失_三情景!$B$32:$D$32,1,MATCH(假设!$B$4,{"悲观","基准","乐观"},0)) | G35: =INDEX(客户数_三情景!$B$32:$D$32,1,MATCH(假设!$B$4,{"悲观","基准","乐观"},0)) | H35: =INDEX(席位数_三情景!$B$32:$D$32,1,MATCH(假设!$B$4,{"悲观","基准","乐观"},0)) | I35: =IF(G35=0,0,L35/G35) | J35: =H35*假设!$B$7 | K35: =J35*12 | L35: =J35 | M35: =假设!$B$24+假设!$B$25*G35+L35*假设!$B$26+假设!$B$29 | N35: =INDEX(客户支持_三情景!$B$32:$D$32,1,MATCH(假设!$B$4,{"悲观","基准","乐观"},0)) | O35: =L35-M35-N35 | P35: =IF(L35=0,0,O35/L35) | Q35: =INDEX(研发_三情景!$B$32:$D$32,1,MATCH(假设!$B$4,{"悲观","基准","乐观"},0)) | R35: =INDEX(销售市场_三情景!$B$32:$D$32,1,MATCH(假设!$B$4,{"悲观","基准","乐观"},0)) | S35: =INDEX(管理行政_三情景!$B$32:$D$32,1,MATCH(假设!$B$4,{"悲观","基准","乐观"},0)) | T35: =O35-Q35-R35-S35 | U35: =T35-W35-X35 | V35: =假设!$B$33+SUM($U$5:U35)+SUM($Y$5:Y35)-SUM($Z$5:Z35) | W35: =INDEX(营运资本_三情景!$B$32:$D$32,1,MATCH(假设!$B$4,{"悲观","基准","乐观"},0)) | X35: =INDEX(税金_三情景!$B$32:$D$32,1,MATCH(假设!$B$4,{"悲观","基准","乐观"},0)) | Y35: =IF($A35=18,假设!$B$35,0) | Z35: =L35*假设!$B$30
A36: 32 | B36: =INDEX(注册量_三情景!$B$33:$D$33,1,MATCH(假设!$B$4,{"悲观","基准","乐观"},0)) | C36: =B36*INDEX(转化率_三情景!$B$33:$D$33,1,MATCH(假设!$B$4,{"悲观","基准","乐观"},0)) | D36: =INDEX(AE数_三情景!$B$33:$D$33,1,MATCH(假设!$B$4,{"悲观","基准","乐观"},0))*INDEX(AE人效_三情景!$B$33:$D$33,1,MATCH(假设!$B$4,{"悲观","基准","乐观"},0)) | E36: =C36+D36 | F36: =INDEX(流失_三情景!$B$33:$D$33,1,MATCH(假设!$B$4,{"悲观","基准","乐观"},0)) | G36: =INDEX(客户数_三情景!$B$33:$D$33,1,MATCH(假设!$B$4,{"悲观","基准","乐观"},0)) | H36: =INDEX(席位数_三情景!$B$33:$D$33,1,MATCH(假设!$B$4,{"悲观","基准","乐观"},0)) | I36: =IF(G36=0,0,L36/G36) | J36: =H36*假设!$B$7 | K36: =J36*12 | L36: =J36 | M36: =假设!$B$24+假设!$B$25*G36+L36*假设!$B$26+假设!$B$29 | N36: =INDEX(客户支持_三情景!$B$33:$D$33,1,MATCH(假设!$B$4,{"悲观","基准","乐观"},0)) | O36: =L36-M36-N36 | P36: =IF(L36=0,0,O36/L36) | Q36: =INDEX(研发_三情景!$B$33:$D$33,1,MATCH(假设!$B$4,{"悲观","基准","乐观"},0)) | R36: =INDEX(销售市场_三情景!$B$33:$D$33,1,MATCH(假设!$B$4,{"悲观","基准","乐观"},0)) | S36: =INDEX(管理行政_三情景!$B$33:$D$33,1,MATCH(假设!$B$4,{"悲观","基准","乐观"},0)) | T36: =O36-Q36-R36-S36 | U36: =T36-W36-X36 | V36: =假设!$B$33+SUM($U$5:U36)+SUM($Y$5:Y36)-SUM($Z$5:Z36) | W36: =INDEX(营运资本_三情景!$B$33:$D$33,1,MATCH(假设!$B$4,{"悲观","基准","乐观"},0)) | X36: =INDEX(税金_三情景!$B$33:$D$33,1,MATCH(假设!$B$4,{"悲观","基准","乐观"},0)) | Y36: =IF($A36=18,假设!$B$35,0) | Z36: =L36*假设!$B$30
A37: 33 | B37: =INDEX(注册量_三情景!$B$34:$D$34,1,MATCH(假设!$B$4,{"悲观","基准","乐观"},0)) | C37: =B37*INDEX(转化率_三情景!$B$34:$D$34,1,MATCH(假设!$B$4,{"悲观","基准","乐观"},0)) | D37: =INDEX(AE数_三情景!$B$34:$D$34,1,MATCH(假设!$B$4,{"悲观","基准","乐观"},0))*INDEX(AE人效_三情景!$B$34:$D$34,1,MATCH(假设!$B$4,{"悲观","基准","乐观"},0)) | E37: =C37+D37 | F37: =INDEX(流失_三情景!$B$34:$D$34,1,MATCH(假设!$B$4,{"悲观","基准","乐观"},0)) | G37: =INDEX(客户数_三情景!$B$34:$D$34,1,MATCH(假设!$B$4,{"悲观","基准","乐观"},0)) | H37: =INDEX(席位数_三情景!$B$34:$D$34,1,MATCH(假设!$B$4,{"悲观","基准","乐观"},0)) | I37: =IF(G37=0,0,L37/G37) | J37: =H37*假设!$B$7 | K37: =J37*12 | L37: =J37 | M37: =假设!$B$24+假设!$B$25*G37+L37*假设!$B$26+假设!$B$29 | N37: =INDEX(客户支持_三情景!$B$34:$D$34,1,MATCH(假设!$B$4,{"悲观","基准","乐观"},0)) | O37: =L37-M37-N37 | P37: =IF(L37=0,0,O37/L37) | Q37: =INDEX(研发_三情景!$B$34:$D$34,1,MATCH(假设!$B$4,{"悲观","基准","乐观"},0)) | R37: =INDEX(销售市场_三情景!$B$34:$D$34,1,MATCH(假设!$B$4,{"悲观","基准","乐观"},0)) | S37: =INDEX(管理行政_三情景!$B$34:$D$34,1,MATCH(假设!$B$4,{"悲观","基准","乐观"},0)) | T37: =O37-Q37-R37-S37 | U37: =T37-W37-X37 | V37: =假设!$B$33+SUM($U$5:U37)+SUM($Y$5:Y37)-SUM($Z$5:Z37) | W37: =INDEX(营运资本_三情景!$B$34:$D$34,1,MATCH(假设!$B$4,{"悲观","基准","乐观"},0)) | X37: =INDEX(税金_三情景!$B$34:$D$34,1,MATCH(假设!$B$4,{"悲观","基准","乐观"},0)) | Y37: =IF($A37=18,假设!$B$35,0) | Z37: =L37*假设!$B$30
A38: 34 | B38: =INDEX(注册量_三情景!$B$35:$D$35,1,MATCH(假设!$B$4,{"悲观","基准","乐观"},0)) | C38: =B38*INDEX(转化率_三情景!$B$35:$D$35,1,MATCH(假设!$B$4,{"悲观","基准","乐观"},0)) | D38: =INDEX(AE数_三情景!$B$35:$D$35,1,MATCH(假设!$B$4,{"悲观","基准","乐观"},0))*INDEX(AE人效_三情景!$B$35:$D$35,1,MATCH(假设!$B$4,{"悲观","基准","乐观"},0)) | E38: =C38+D38 | F38: =INDEX(流失_三情景!$B$35:$D$35,1,MATCH(假设!$B$4,{"悲观","基准","乐观"},0)) | G38: =INDEX(客户数_三情景!$B$35:$D$35,1,MATCH(假设!$B$4,{"悲观","基准","乐观"},0)) | H38: =INDEX(席位数_三情景!$B$35:$D$35,1,MATCH(假设!$B$4,{"悲观","基准","乐观"},0)) | I38: =IF(G38=0,0,L38/G38) | J38: =H38*假设!$B$7 | K38: =J38*12 | L38: =J38 | M38: =假设!$B$24+假设!$B$25*G38+L38*假设!$B$26+假设!$B$29 | N38: =INDEX(客户支持_三情景!$B$35:$D$35,1,MATCH(假设!$B$4,{"悲观","基准","乐观"},0)) | O38: =L38-M38-N38 | P38: =IF(L38=0,0,O38/L38) | Q38: =INDEX(研发_三情景!$B$35:$D$35,1,MATCH(假设!$B$4,{"悲观","基准","乐观"},0)) | R38: =INDEX(销售市场_三情景!$B$35:$D$35,1,MATCH(假设!$B$4,{"悲观","基准","乐观"},0)) | S38: =INDEX(管理行政_三情景!$B$35:$D$35,1,MATCH(假设!$B$4,{"悲观","基准","乐观"},0)) | T38: =O38-Q38-R38-S38 | U38: =T38-W38-X38 | V38: =假设!$B$33+SUM($U$5:U38)+SUM($Y$5:Y38)-SUM($Z$5:Z38) | W38: =INDEX(营运资本_三情景!$B$35:$D$35,1,MATCH(假设!$B$4,{"悲观","基准","乐观"},0)) | X38: =INDEX(税金_三情景!$B$35:$D$35,1,MATCH(假设!$B$4,{"悲观","基准","乐观"},0)) | Y38: =IF($A38=18,假设!$B$35,0) | Z38: =L38*假设!$B$30
A39: 35 | B39: =INDEX(注册量_三情景!$B$36:$D$36,1,MATCH(假设!$B$4,{"悲观","基准","乐观"},0)) | C39: =B39*INDEX(转化率_三情景!$B$36:$D$36,1,MATCH(假设!$B$4,{"悲观","基准","乐观"},0)) | D39: =INDEX(AE数_三情景!$B$36:$D$36,1,MATCH(假设!$B$4,{"悲观","基准","乐观"},0))*INDEX(AE人效_三情景!$B$36:$D$36,1,MATCH(假设!$B$4,{"悲观","基准","乐观"},0)) | E39: =C39+D39 | F39: =INDEX(流失_三情景!$B$36:$D$36,1,MATCH(假设!$B$4,{"悲观","基准","乐观"},0)) | G39: =INDEX(客户数_三情景!$B$36:$D$36,1,MATCH(假设!$B$4,{"悲观","基准","乐观"},0)) | H39: =INDEX(席位数_三情景!$B$36:$D$36,1,MATCH(假设!$B$4,{"悲观","基准","乐观"},0)) | I39: =IF(G39=0,0,L39/G39) | J39: =H39*假设!$B$7 | K39: =J39*12 | L39: =J39 | M39: =假设!$B$24+假设!$B$25*G39+L39*假设!$B$26+假设!$B$29 | N39: =INDEX(客户支持_三情景!$B$36:$D$36,1,MATCH(假设!$B$4,{"悲观","基准","乐观"},0)) | O39: =L39-M39-N39 | P39: =IF(L39=0,0,O39/L39) | Q39: =INDEX(研发_三情景!$B$36:$D$36,1,MATCH(假设!$B$4,{"悲观","基准","乐观"},0)) | R39: =INDEX(销售市场_三情景!$B$36:$D$36,1,MATCH(假设!$B$4,{"悲观","基准","乐观"},0)) | S39: =INDEX(管理行政_三情景!$B$36:$D$36,1,MATCH(假设!$B$4,{"悲观","基准","乐观"},0)) | T39: =O39-Q39-R39-S39 | U39: =T39-W39-X39 | V39: =假设!$B$33+SUM($U$5:U39)+SUM($Y$5:Y39)-SUM($Z$5:Z39) | W39: =INDEX(营运资本_三情景!$B$36:$D$36,1,MATCH(假设!$B$4,{"悲观","基准","乐观"},0)) | X39: =INDEX(税金_三情景!$B$36:$D$36,1,MATCH(假设!$B$4,{"悲观","基准","乐观"},0)) | Y39: =IF($A39=18,假设!$B$35,0) | Z39: =L39*假设!$B$30
A40: 36 | B40: =INDEX(注册量_三情景!$B$37:$D$37,1,MATCH(假设!$B$4,{"悲观","基准","乐观"},0)) | C40: =B40*INDEX(转化率_三情景!$B$37:$D$37,1,MATCH(假设!$B$4,{"悲观","基准","乐观"},0)) | D40: =INDEX(AE数_三情景!$B$37:$D$37,1,MATCH(假设!$B$4,{"悲观","基准","乐观"},0))*INDEX(AE人效_三情景!$B$37:$D$37,1,MATCH(假设!$B$4,{"悲观","基准","乐观"},0)) | E40: =C40+D40 | F40: =INDEX(流失_三情景!$B$37:$D$37,1,MATCH(假设!$B$4,{"悲观","基准","乐观"},0)) | G40: =INDEX(客户数_三情景!$B$37:$D$37,1,MATCH(假设!$B$4,{"悲观","基准","乐观"},0)) | H40: =INDEX(席位数_三情景!$B$37:$D$37,1,MATCH(假设!$B$4,{"悲观","基准","乐观"},0)) | I40: =IF(G40=0,0,L40/G40) | J40: =H40*假设!$B$7 | K40: =J40*12 | L40: =J40 | M40: =假设!$B$24+假设!$B$25*G40+L40*假设!$B$26+假设!$B$29 | N40: =INDEX(客户支持_三情景!$B$37:$D$37,1,MATCH(假设!$B$4,{"悲观","基准","乐观"},0)) | O40: =L40-M40-N40 | P40: =IF(L40=0,0,O40/L40) | Q40: =INDEX(研发_三情景!$B$37:$D$37,1,MATCH(假设!$B$4,{"悲观","基准","乐观"},0)) | R40: =INDEX(销售市场_三情景!$B$37:$D$37,1,MATCH(假设!$B$4,{"悲观","基准","乐观"},0)) | S40: =INDEX(管理行政_三情景!$B$37:$D$37,1,MATCH(假设!$B$4,{"悲观","基准","乐观"},0)) | T40: =O40-Q40-R40-S40 | U40: =T40-W40-X40 | V40: =假设!$B$33+SUM($U$5:U40)+SUM($Y$5:Y40)-SUM($Z$5:Z40) | W40: =INDEX(营运资本_三情景!$B$37:$D$37,1,MATCH(假设!$B$4,{"悲观","基准","乐观"},0)) | X40: =INDEX(税金_三情景!$B$37:$D$37,1,MATCH(假设!$B$4,{"悲观","基准","乐观"},0)) | Y40: =IF($A40=18,假设!$B$35,0) | Z40: =L40*假设!$B$30

Sheet 年度汇总
A1: 年度汇总 · 基准情景（三年）
A2: 取自「月度模型」的年度加总。EBITDA 为负表示仍在投入期。
A4: 科目 | B4: Y1 | C4: Y2 | D4: Y3 | E4: Y3 占收入
A5: 收入 | B5: 214943.2 | C5: 1213710.2 | D5: 3353565.5 | E5: 1
A6: 服务器与基础设施 + 支付通道 | B6: 145714.18 | C6: 325310.65 | D6: 557863.17 | E6: =IF($B$5=0,"",D6/$D$5)
A7: 毛利 | B7: 69229.019 | C7: 888399.59 | D7: 2795702.3 | E7: =IF($B$5=0,"",D7/$D$5)
A8: 毛利率 | B8: 0.32208053 | C8: 0.73197008 | D8: 0.83365073 | E8: =IF($B$5=0,"",D8/$D$5)
A9: 研发 + 产品 | B9: 646472.22 | C9: 1048611.1 | D9: 1548833.3 | E9: =IF($B$5=0,"",D9/$D$5)
A10: 销售与市场（含获客） | B10: 481816.67 | C10: 1075033.3 | D10: 1642166.7 | E10: =IF($B$5=0,"",D10/$D$5)
A11: 管理与行政 | B11: 278000 | C11: 332083.33 | D11: 396000 | E11: =IF($B$5=0,"",D11/$D$5)
A12: EBITDA | B12: -1337059.9 | C12: -1567328.2 | D12: -791297.67 | E12: =IF($B$5=0,"",D12/$D$5)
A13: EBITDA 利润率 | B13: -6.2205265 | C13: -1.2913529 | D13: -0.23595712 | E13: =IF($B$5=0,"",D13/$D$5)
A14: 期末 ARR | B14: 485565.53 | C14: 2004425.1 | D14: 4627347.1 | E14: =IF($B$5=0,"",D14/$D$5)
A15: ARR 同比增速 | C15: 3.1280217 | D15: 1.3085658 | E15: =IF($B$5=0,"",D15/$D$5)
A16: 经营现金流 | B16: -1254749 | C16: -1521411.2 | D16: -1480408.6 | E16: =IF($B$5=0,"",D16/$D$5)
A17: 期末现金 | B17: 2242671.7 | C17: 12706696 | D17: 11186045 | E17: =IF($B$5=0,"",D17/$D$5)
A18: 期末付费客户数 | B18: 99.859905 | C18: 356.31798 | D18: 714.19979 | E18: =IF($B$5=0,"",D18/$D$5)
A19: 平均团队人数 | B19: 11.868056 | C19: 21.652778 | D19: 32.395833 | E19: =IF($B$5=0,"",D19/$D$5)
A20: 人效 ARR/人 | B20: 40913.655 | C20: 92571.267 | D20: 142837.72 | E20: =IF($B$5=0,"",D20/$D$5)

Sheet 单位经济
A1: 单位经济与 SaaS 指标看板
A2: 绿色=达标，黄色=临界，红色=未达标。行业带来源见报告第十节。
A4: 指标 | B4: 基准 M12 | C4: 基准 M24 | D4: 基准 M36 | E4: 行业健康带 | F4: 判定 | G4: 说明
A5: 直接 CAC (US$) | B5: 1106.3465 | C5: 750.06626 | D5: 675.04836 | E5: $500–700 | F5: 达标 | G5: 营销支出 ÷ 新客
A6: 全载 CAC (US$) | B6: 3811.4637 | C6: 3052.9788 | D6: 2809.1554 | E6: — | F6: 达标 | G6: 含销售与市场人力，投资人口径
A7: CAC 回收期 (月) | B7: 16.423548 | C7: 8.3025224 | D7: 6.0282522 | E7: 6–12 月 | F7: 达标 | G7: 毛利口径：CAC ÷ (ARPU × 毛利率)
A8: LTV/CAC | B8: 1.7497086 | C8: 3.6849135 | D8: 5.5028158 | E8: 3–5x | F8: 临界 | G8: 恒等式：1 ÷ (流失率 × 回收期)
A9: 月流失率 | B9: 0.034799042 | C9: 0.032686065 | D9: 0.030145578 | E9: 2.8–4.8% | F9: 达标 | G9: PLG 与销售客分群混合
A10: GRR (12月cohort) | B10: 0 | C10: 0.63638866 | D10: 0.6591356 | E10: 60–78% | F10: 达标 | G10: 剔除席位扩张的 cohort 留存
A11: NRR (12月cohort) | B11: 0 | C11: 0.79296648 | D11: 0.82131011 | E11: 75–95%（A轮要 ≥100%） | F11: 达标 | G11: 含席位扩张；A 轮硬伤项
A12: 毛利率 | B12: 0.57272924 | C12: 0.78440957 | D12: 0.86308435 | E12: 78–90% | F12: 达标 | G12: 纯软件 80% 中位
A13: 烧钱倍数 | D13: 0.56441197 | E13: < 1.5x | F13: 达标 | G13: 净消耗 ÷ 净新增 ARR
A14: Rule of 40 | D14: 107.26086 | E14: > 40 | F14: 达标 | G14: ARR 增速% + EBITDA 利润率%
A15: 人效 ARR/人 (Y3) | D15: 142837.72 | E15: 中位 $175K | F15: 临界 | G15: Benchmarkit 2026

Sheet 情景对比
A1: 三情景对比
A2: 同一套模型跑三组参数。基准参数经 81 组扫描按行业基准带校准。
A4: 指标 | B4: 悲观 | C4: 基准 | D4: 乐观 | E4: 备注
A5: M36 ARR | B5: 1189042.8 | C5: 4627347.1 | D5: 8860579.3 | E5: 基准约 $4.6M
A6: M36 MRR | B6: 99086.899 | C6: 385612.26 | D6: 738381.61
A7: M36 付费客户数 | B7: 251.41154 | C7: 714.19979 | D7: 1220.6397
A8: M36 ARPU | B8: 394.12231 | C8: 539.92211 | D8: 604.91363 | E8: 含席位扩张
A9: Y1 收入 | B9: 98745.816 | C9: 214943.2 | D9: 339587.65
A10: Y2 收入 | B10: 417683.3 | C10: 1213710.2 | D10: 2088661.2
A11: Y3 收入 | B11: 925170.21 | C11: 3353565.5 | D11: 6232315.7
A12: Y1 EBITDA | B12: -1771488.3 | C12: -1337059.9 | D12: -1230002.6
A13: Y2 EBITDA | B13: -2823657.2 | C13: -1567328.2 | D13: -760789.39
A14: Y3 EBITDA | B14: -3736309.6 | C14: -791297.67 | D14: 1915044.7 | E14: 负=仍在投入期
A15: 现金谷 | B15: -3631324.5 | C15: 1632596.3 | D15: 2347029.8 | E15: 含 A 轮
A16: 现金谷月份 | B16: 32 | C16: 17 | D16: 13
A17: 经营盈亏平衡月 | B17: 99 | C17: 36 | D17: 25 | E17: 3年内未达=99
A18: M36 月流失率 | B18: 0.054149619 | C18: 0.030145578 | D18: 0.022841027
A19: M36 CAC 回收期(月) | B19: 29.941737 | C19: 6.0282522 | D19: 3.2823997 | E19: 毛利口径
A20: M36 LTV/CAC | B20: 0.6167762 | C20: 5.5028158 | D20: 13.338068
A21: M36 GRR | B21: 0.48190386 | C21: 0.6591356 | D21: 0.73013137
A22: M36 NRR | B22: 0.52710976 | C22: 0.82131011 | D22: 0.98194552 | E22: A 轮要 ≥100%
A23: Y3 Rule of 40 | B23: -313.1391 | C23: 107.26086 | D23: 179.99571
A24: Y3 烧钱倍数 | B24: 6.8202938 | C24: 0.56441197 | D24: -0.11227801
A25: Y3 人效 ARR/人 | B25: 30407.061 | C25: 142837.72 | D25: 273509.84 | E25: 中位 $175K
A26: A 轮时点(月) | B26: 33 | C26: 18 | D26: 14 | E26: ARR 过 $1M 的月份
A27: A 轮规模 | B27: 12000000 | C27: 12000000 | D27: 12000000 | E27: 市场标准 $12M
A28: A 轮投后 | B28: 67039106 | C28: 67039106 | D28: 67039106 | E28: Carta 中位 $67.7M
A29: 生存所需资金 | B29: 5258456.2 | C29: 413084.7 | D29: 0 | E29: 现金层面最小额

Sheet 融资节奏
A1: 融资节奏建议（基准情景）
A2: 时点由 ARR 门槛推导，规模由市场标准反推。生存所需资金仅作下限参考。
A4: 项目 | B4: 时点 | C4: 金额 | D4: 投后估值 | E4: 稀释 | F4: 触发条件
A5: Seed | B5: M0 | C5: 3500000 | D5: 20000000 | E5: 0.175 | F5: 产品上线 + 前 10 个付费客户。Carta SaaS 种子轮中位：$4.1M 募资 / $23.4M 投后 / 19–20% 稀释
A6: Series A | B6: M18 | C6: 12000000 | D6: 67039106 | E6: 0.179 | F6: ARR 过 $1M（打款时 1096K）+ 月增速 >15% + NRR ≥ 100%
A7: Series B | B7: M33–36 | C7: 30000000 | D7: 200000000 | E7: 0.13 | F7: ARR $8–15M + 烧钱倍数 <1.0x。基准 M36 ARR 4.63M，刚卡在门槛边缘
A9: 关键推导
A10: 无 A 轮时现金击穿月 | B10: M28 | C10: 低于 $300K 安全线
A11: ARR $1M 达成月（A 轮门槛） | B11: M18 | C11: Carta 主流门槛 $1–3M
A12: 应开始接触投资人 | B12: M13 | C12: 首次会面到打款需 4–6 个月
A13: 打款时 ARR | B13: $1096K | C13: 必须 ≥ $800K–1M 绝对下限
A14: 月烧钱速度 | B14: $119K | C14: 无 A 轮情形
A15: 生存所需资金 | B15: $0.4M | C15: 现金层面最小额
A16: 24 个月计划所需 | B16: $1.7M | C16: 按当前烧钱速度
A17: 建议规模（市场标准） | B17: $12M | C17: Carta A 轮中位 $12M
A18: 投入不足信号 | B18: 97% | C18: 现金够活，但计划撑不起 $5M+ ARR 目标
A20: 稀释路径（Carta 2025 基准对照）
A21: 成立时 | B21: 100% | C21: Carta 100%
A22: Seed 后 | B22: 82.5% | C22: Carta 56.2%
A23: Series A 后 | B23: 67.7% | C23: Carta 36.1%

Sheet Cohort留存
A1: Cohort 留存矩阵 · 基准情景
A2: 行=获客月，列=队列年龄(M0–M12)，数值=存活 logo 占比。早期队列同时受合同结构与年约升级影响。
A4: 获客月 | B4: M0 | C4: M1 | D4: M2 | E4: M3 | F4: M4 | G4: M5 | H4: M6 | I4: M7 | J4: M8 | K4: M9 | L4: M10 | M4: M11 | N4: M12
A5: M1 | B5: 100 | C5: 95.5 | D5: 91.4 | E5: 87.5 | F5: 83.8 | G5: 80.4 | H5: 77.2 | I5: 74.2 | J5: 71.3 | K5: 68.7 | L5: 66.2 | M5: 63.8 | N5: 61.6
A6: M2 | B6: 100 | C6: 95.6 | D6: 91.4 | E6: 87.5 | F6: 83.9 | G6: 80.5 | H6: 77.3 | I6: 74.3 | J6: 71.5 | K6: 68.8 | L6: 66.3 | M6: 64 | N6: 61.7
A7: M3 | B7: 100 | C7: 95.6 | D7: 91.5 | E7: 87.6 | F7: 84 | G7: 80.6 | H7: 77.4 | I7: 74.5 | J7: 71.6 | K7: 69 | L7: 66.5 | M7: 64.2 | N7: 61.9
A8: M4 | B8: 100 | C8: 95.6 | D8: 91.5 | E8: 87.7 | F8: 84.1 | G8: 80.7 | H8: 77.6 | I8: 74.6 | J8: 71.8 | K8: 69.2 | L8: 66.7 | M8: 64.3 | N8: 62.1
A9: M5 | B9: 100 | C9: 95.6 | D9: 91.6 | E9: 87.8 | F9: 84.2 | G9: 80.8 | H9: 77.7 | I9: 74.7 | J9: 72 | K9: 69.3 | L9: 66.9 | M9: 64.5 | N9: 62.3
A10: M6 | B10: 100 | C10: 95.7 | D10: 91.6 | E10: 87.8 | F10: 84.3 | G10: 81 | H10: 77.8 | I10: 74.9 | J10: 72.1 | K10: 69.5 | L10: 67 | M10: 64.7 | N10: 62.5
A11: M7 | B11: 100 | C11: 95.7 | D11: 91.7 | E11: 87.9 | F11: 84.4 | G11: 81.1 | H11: 78 | I11: 75 | J11: 72.3 | K11: 69.7 | L11: 67.2 | M11: 64.9 | N11: 62.7
A12: M8 | B12: 100 | C12: 95.7 | D12: 91.7 | E12: 88 | F12: 84.5 | G12: 81.2 | H12: 78.1 | I12: 75.2 | J12: 72.4 | K12: 69.8 | L12: 67.4 | M12: 65.1 | N12: 62.9
A13: M9 | B13: 100 | C13: 95.8 | D13: 91.8 | E13: 88.1 | F13: 84.6 | G13: 81.3 | H13: 78.2 | I13: 75.3 | J13: 72.6 | K13: 70 | L13: 67.6 | M13: 65.3 | N13: 63.1
A14: M10 | B14: 100 | C14: 95.8 | D14: 91.8 | E14: 88.1 | F14: 84.7 | G14: 81.4 | H14: 78.3 | I14: 75.5 | J14: 72.7 | K14: 70.2 | L14: 67.7 | M14: 65.4 | N14: 63.3
A15: M11 | B15: 100 | C15: 95.8 | D15: 91.9 | E15: 88.2 | F15: 84.8 | G15: 81.5 | H15: 78.5 | I15: 75.6 | J15: 72.9 | K15: 70.3 | L15: 67.9 | M15: 65.6 | N15: 63.4
A16: M12 | B16: 100 | C16: 95.8 | D16: 91.9 | E16: 88.3 | F16: 84.9 | G16: 81.6 | H16: 78.6 | I16: 75.7 | J16: 73 | K16: 70.5 | L16: 68.1 | M16: 65.8 | N16: 63.6
... A28: M24 | B28: 100 | C28: 96.2 | D28: 92.6 | E28: 89.2 | F28: 86 | G28: 83 | H28: 80.1 | I28: 77.4 | J28: 74.9 | K28: 72.5 | L28: 70.2 | M28: 68 | N28: 65.9

Sheet 瀑布桥
A1: Y3 收入 → EBITDA 瀑布桥 · 三情景
A2: 每一段扣减都对应成本表的一个科目。基准情景 Y3 收入约 $3.35M。
A4: 基准 情景
A5: 科目 | B5: 金额(US$) | C5: 占收入 | D5: 累计 | F5: 说明
A6: 收入 | B6: 3353565.5 | C6: 1 | D6: 3353565.5 | F6: 收入
A7: 服务器+支付+支持 | B7: -557863.17 | C7: -0.16634927 | D7: 2795702.3
A8: 毛利 | B8: 2795702.3 | C8: 0.83365073 | D8: 2795702.3 | F8: 毛利
A9: 研发+产品 | B9: -1548833.3 | C9: -0.46184675 | D9: 1246869
A10: 销售与市场 | B10: -1642166.7 | C10: -0.48967783 | D10: -395297.67
A11: 管理行政 | B11: -396000 | C11: -0.11808328 | D11: -791297.67
A12: EBITDA | B12: -791297.67 | C12: -0.23595712 | D12: -791297.67 | F12: EBITDA
A13: 毛利率 | B13: 0.83365073 | F13: 毛利 / 收入
A16: 乐观 情景
A17: 科目 | B17: 金额(US$) | C17: 占收入 | D17: 累计 | F17: 说明
A18: 收入 | B18: 6232315.7 | C18: 1 | D18: 6232315.7 | F18: 收入
A19: 服务器+支付+支持 | B19: -677191.02 | C19: -0.10865801 | D19: 5555124.7
A20: 毛利 | B20: 5555124.7 | C20: 0.89134199 | D20: 5555124.7 | F20: 毛利
A21: 研发+产品 | B21: -1548833.3 | C21: -0.24851651 | D21: 4006291.4
A22: 销售与市场 | B22: -1695246.7 | C22: -0.27200911 | D22: 2311044.7
A23: 管理行政 | B23: -396000 | C23: -0.063539785 | D23: 1915044.7
A24: EBITDA | B24: 1915044.7 | C24: 0.30727659 | D24: 1915044.7 | F24: EBITDA
A25: 毛利率 | B25: 0.89134199 | F25: 毛利 / 收入
A28: 悲观 情景
A29: 科目 | B29: 金额(US$) | C29: 占收入 | D29: 累计 | F29: 说明
A30: 收入 | B30: 925170.21 | C30: 1 | D30: 925170.21 | F30: 收入
A31: 服务器+支付+支持 | B31: -375963.19 | C31: -0.40637191 | D31: 549207.02
A32: 毛利 | B32: 549207.02 | C32: 0.59362809 | D32: 549207.02 | F32: 毛利
A33: 研发+产品 | B33: -1778833.3 | C33: -1.9227093 | D33: -1229626.3
A34: 销售与市场 | B34: -1992683.3 | C34: -2.1538559 | D34: -3222309.6
A35: 管理行政 | B35: -514000 | C35: -0.55557344 | D35: -3736309.6
A36: EBITDA | B36: -3736309.6 | C36: -4.0385105 | D36: -3736309.6 | F36: EBITDA
A37: 毛利率 | B37: 0.59362809 | F37: 毛利 / 收入

Sheet 行动清单
A1: 90 天行动清单 · 从模型到动作
A2: 每条对应模型里的一个敏感参数。P0=立刻做，P1=本季度，P2=持续。
A4: 优先级 | B4: 时间窗 | C4: 任务 | D4: 说明 | E4: 负责人 | F4: 验收标准
A5: P0 | B5: 第 1–2 周 | C5: 把 PLG 注册→付费转化拆成漏斗看板 | D5: 按注册周分群追踪，锁定 3.2%→4.0% 的爬坡路径。当前模型最脆弱的假设之一。 | E5: 增长负责人 | F5: 转化率 ≥3.5%
A6: P0 | B6: 第 1–2 周 | C6: 年约合同默认化改造 | D6: 把月付默认改为年约默认+月付可选。当前销售客年约占比 62%，目标 75%。 | E6: 产品+销售 | F6: 年约占比 ≥70%
A7: P0 | B7: 第 2–4 周 | C7: 同群客户席位扩张归因 | D7: 建立 12 个月 cohort 的席位追踪表，验证 1.85%/月 扩张率真实性。NRR 全部押在这个数上。 | E7: 数据分析 | F7: 席位扩张 ≥1.5%/月
A8: P1 | B8: 第 3–6 周 | C8: 单注册成本压到 $26 以下 | D8: SEO/内容/口碑三线并进。参考 ClickUp 40% 新注册来自口碑的结构性红利。 | E8: 市场负责人 | F8: CAC 回收 ≤9 月
A9: P1 | B9: 第 4–8 周 | C9: AE 人效爬坡实验 | D9: 新人 AE 前 6 个月人效只有成熟期 40–60%，提前设计扶持机制与产品化辅助。 | E9: 销售负责人 | F9: M18 人效 ≥1.4
A10: P1 | B10: 第 6–10 周 | C10: 用量包/AI 席位产品化预研 | D10: 按用量定价公司 NDR 中位 108% vs 按席位 98%，这 10 个百分点是防御性布局。 | E10: 产品负责人 | F10: MVP 方案成型
A11: P2 | B11: 第 8–12 周 | C11: A 轮材料与投资人接触准备 | D11: M13 开始接触。需准备：cohort 留存表、单位经济三件套、月度现金表。 | E11: CEO+财务 | F11: 3 家机构首会
A12: P2 | B12: 第 10–13 周 | C12: GRR/NRR 双指标看板上线 | D12: 区分 GRR 与 NRR。NRR 高但 GRR 低意味着少数大客户掩盖多数流失，不可持续。 | E12: 财务+分析 | F12: GRR ≥68%
A13: P2 | B13: 第 12 周 | C13: 成本冻结预案预置 | D13: 若 Y2 后 ARR 增速跌破 60%，研发绝对额立即冻结。当前 Y3 研发占收入 40%，无缓冲。 | E13: CEO | F13: 预案就位

Sheet 路线图
A1: 12 个月路线图 · 基准情景
A2: ARR 里程碑由模型推导；验收标准对应模型中的健康带。
A4: 季度 | B4: 主题 | C4: ARR 目标 | D4: 重点动作 | E4: 验收标准
A5: Q1 | B5: 验证 PMF | C5: ARR $0.5M | D5: PLG 转化爬坡到 3.5%、年约占比提至 60%、留存表上线 | E5: NRR ≥90%，月流失 ≤4.5%
A6: Q2 | B6: 跨过门槛 | C6: ARR $1.0M | D6: ARR 破 $1M，接触投资人，A 轮材料定稿 | E6: A 轮材料就绪，M13 首会
A7: Q3 | B7: A 轮 + 扩张 | C7: ARR $1.6M | D7: A 轮 M18 打款 $12M，团队翻倍至 35 人，席位扩张率守住 | E7: A 轮到位，MRR 增速 ≥10%/月
A8: Q4 | B8: 单位经济 | C8: ARR $2.2M | D8: CAC 回收压进 6 月，S&M 占比开始下降，GRR 稳定 70%+ | E8: 烧钱倍数 <1.5x，ARR/员工 ≥$150K

Sheet 敏感性
A1: 敏感性分析 · M36 ARR（US$M）
A2: 行=获客成本（单注册成本）倍数，列=流失率倍数。基准=中心格。
A4: 获客成本 \ 流失率 | B4: ×0.8 | C4: ×1 | D4: ×1.25 | E4: ×1.5
A5: ×0.7 | B5: 4.95 | C5: 4.63 | D5: 4.28 | E5: 3.99
A6: ×1 | B6: 4.95 | C6: 4.63 | D6: 4.28 | E6: 3.99
A7: ×1.4 | B7: 4.95 | C7: 4.63 | D7: 4.28 | E7: 3.99
A8: ×1.9 | B8: 4.95 | C8: 4.63 | D8: 4.28 | E8: 3.99
A10: 同网格的 CAC 回收期（月）
A11: 获客成本 \ 流失率 | B11: ×0.8 | C11: ×1 | D11: ×1.25 | E11: ×1.5
A12: ×0.7 | B12: 5.6 | C12: 5.6 | D12: 5.7 | E12: 5.8
A13: ×1 | B13: 6 | C13: 6 | D13: 6.1 | E13: 6.2
A14: ×1.4 | B14: 6.5 | C14: 6.5 | D14: 6.6 | E14: 6.7
