Workbook

Sheet 参会名单
A1: 编号 | B1: 姓名 | C1: 公司 | D1: 职位 | E1: 邮箱 | F1: 手机 | G1: 票种 | H1: 餐食偏好 | I1: T恤尺码 | J1: 报名日期 | K1: 签到状态
A2: 1 | B2: 何琪然 | C2: 星环动力 | D2: 技术副总裁 | E2: heqiran01@stellar-ring.com | F2: 13666724660 | G2: VIP | H2: 无麸质 | I2: M | J2: 46124 | K2: 已签到
A3: 2 | B3: 杨杰彤 | C3: 领航智造 | D3: 技术副总裁 | E3: yangjietong02@navi-mfg.com | F3: 13642943415 | G3: VIP | H3: 素食 | I3: L | J3: 46111 | K3: 已签到
A4: 3 | B4: 林然伟 | C4: 南岭智联 | D4: 首席架构师 | E4: linranwei03@nanling-iot.cn | F4: 18804099078 | G4: VIP | H4: 标准 | I4: M | J4: 46151 | K4: 已签到
A5: 4 | B5: 高怡刚 | C5: 星瀚科技 | D5: 研发总监 | E5: gaoyigang04@xinghan-tech.com | F5: 13648081540 | G5: VIP | H5: 素食 | I5: M | J5: 46135 | K5: 已签到
A6: 5 | B6: 何文洋 | C6: 领航智造 | D6: 技术副总裁 | E6: hewenyang05@navi-mfg.com | F6: 13873273561 | G6: VIP | H6: 标准 | I6: L | J6: 46100 | K6: 已签到
A7: 6 | B7: 郑磊 | C7: 蓝图网络 | D7: 技术副总裁 | E7: zhenglei06@lantoo.net | F7: 13627879060 | G7: VIP | H7: 无麸质 | I7: M | J7: 46112 | K7: 已签到
A8: 7 | B8: 王文芳 | C8: 南岭智联 | D8: 研发总监 | E8: wangwenfang07@nanling-iot.cn | F8: 13541398578 | G8: VIP | H8: 标准 | I8: L | J8: 46110 | K8: 已签到
A9: 8 | B9: 潘涵 | C9: 星瀚科技 | D9: 技术副总裁 | E9: panhan08@xinghan-tech.com | F9: 13896242196 | G9: VIP | H9: 标准 | I9: M | J9: 46113 | K9: 已签到
A10: 9 | B10: 冯勇宁 | C10: 天工智能 | D10: CTO | E10: fengyongning09@tiangong-ai.com | F10: 13806917835 | G10: VIP | H10: 标准 | I10: XL | J10: 46144 | K10: 已签到
A11: 10 | B11: 陈超芳 | C11: 万象云 | D11: 技术合伙人 | E11: chenchaofang10@wanxiang-cloud.cn | F11: 15814164504 | G11: VIP | H11: 清真 | I11: M | J11: 46115 | K11: 未签到
A12: 11 | B12: 高欣彤 | C12: 云栖智能 | D12: CTO | E12: gaoxintong11@yunqi-ai.com | F12: 13613738789 | G12: VIP | H12: 清真 | I12: M | J12: 46145 | K12: 已签到
A13: 12 | B13: 高宇丽 | C13: 智汇云 | D13: 技术副总裁 | E13: gaoyuli12@zhihui-cloud.com | F13: 15827394901 | G13: VIP | H13: 标准 | I13: M | J13: 46135 | K13: 已签到
... A201: 200 | B201: 孙嘉 | C201: 启元软件 | D201: BD 总监 | E201: sunjia200@qiyuan-soft.com | F201: 13516637548 | G201: 赞助商 | H201: 清真 | I201: L | J201: 46145 | K201: 已签到

Sheet 签到追踪表
A1: 编号 | B1: 姓名 | C1: 公司 | D1: 票种 | E1: 签到状态 | F1: 签到时间 | G1: 签到方式 | H1: 礼品领取 | I1: 备注
A2: 1 | B2: =IFERROR(VLOOKUP($A2,参会名单!$A$2:$K$201,2,FALSE),"") -> 何琪然 | C2: =IFERROR(VLOOKUP($A2,参会名单!$A$2:$K$201,3,FALSE),"") -> 星环动力 | D2: =IFERROR(VLOOKUP($A2,参会名单!$A$2:$K$201,7,FALSE),"") -> VIP | E2: 已签到 | F2: 0.33611111 | G2: 扫码 | H2: 是
A3: 2 | B3: =IFERROR(VLOOKUP($A3,参会名单!$A$2:$K$201,2,FALSE),"") -> 杨杰彤 | C3: =IFERROR(VLOOKUP($A3,参会名单!$A$2:$K$201,3,FALSE),"") -> 领航智造 | D3: =IFERROR(VLOOKUP($A3,参会名单!$A$2:$K$201,7,FALSE),"") -> VIP | E3: 已签到 | F3: 0.3375 | G3: 前台登记 | H3: 是
A4: 3 | B4: =IFERROR(VLOOKUP($A4,参会名单!$A$2:$K$201,2,FALSE),"") -> 林然伟 | C4: =IFERROR(VLOOKUP($A4,参会名单!$A$2:$K$201,3,FALSE),"") -> 南岭智联 | D4: =IFERROR(VLOOKUP($A4,参会名单!$A$2:$K$201,7,FALSE),"") -> VIP | E4: 已签到 | F4: 0.37152778 | G4: 扫码 | H4: 是
A5: 4 | B5: =IFERROR(VLOOKUP($A5,参会名单!$A$2:$K$201,2,FALSE),"") -> 高怡刚 | C5: =IFERROR(VLOOKUP($A5,参会名单!$A$2:$K$201,3,FALSE),"") -> 星瀚科技 | D5: =IFERROR(VLOOKUP($A5,参会名单!$A$2:$K$201,7,FALSE),"") -> VIP | E5: 已签到 | F5: 0.37013889 | G5: 人脸识别 | H5: 是
A6: 5 | B6: =IFERROR(VLOOKUP($A6,参会名单!$A$2:$K$201,2,FALSE),"") -> 何文洋 | C6: =IFERROR(VLOOKUP($A6,参会名单!$A$2:$K$201,3,FALSE),"") -> 领航智造 | D6: =IFERROR(VLOOKUP($A6,参会名单!$A$2:$K$201,7,FALSE),"") -> VIP | E6: 已签到 | F6: 0.35277778 | G6: 人脸识别 | H6: 是
A7: 6 | B7: =IFERROR(VLOOKUP($A7,参会名单!$A$2:$K$201,2,FALSE),"") -> 郑磊 | C7: =IFERROR(VLOOKUP($A7,参会名单!$A$2:$K$201,3,FALSE),"") -> 蓝图网络 | D7: =IFERROR(VLOOKUP($A7,参会名单!$A$2:$K$201,7,FALSE),"") -> VIP | E7: 已签到 | F7: 0.36666667 | G7: 扫码 | H7: 是
A8: 7 | B8: =IFERROR(VLOOKUP($A8,参会名单!$A$2:$K$201,2,FALSE),"") -> 王文芳 | C8: =IFERROR(VLOOKUP($A8,参会名单!$A$2:$K$201,3,FALSE),"") -> 南岭智联 | D8: =IFERROR(VLOOKUP($A8,参会名单!$A$2:$K$201,7,FALSE),"") -> VIP | E8: 已签到 | F8: 0.33819444 | G8: 扫码 | H8: 否
A9: 8 | B9: =IFERROR(VLOOKUP($A9,参会名单!$A$2:$K$201,2,FALSE),"") -> 潘涵 | C9: =IFERROR(VLOOKUP($A9,参会名单!$A$2:$K$201,3,FALSE),"") -> 星瀚科技 | D9: =IFERROR(VLOOKUP($A9,参会名单!$A$2:$K$201,7,FALSE),"") -> VIP | E9: 已签到 | F9: 0.35277778 | G9: 扫码 | H9: 是 | I9: 媒体嘉宾，需安排采访位
A10: 9 | B10: =IFERROR(VLOOKUP($A10,参会名单!$A$2:$K$201,2,FALSE),"") -> 冯勇宁 | C10: =IFERROR(VLOOKUP($A10,参会名单!$A$2:$K$201,3,FALSE),"") -> 天工智能 | D10: =IFERROR(VLOOKUP($A10,参会名单!$A$2:$K$201,7,FALSE),"") -> VIP | E10: 已签到 | F10: 0.37083333 | G10: 扫码 | H10: 是
A11: 10 | B11: =IFERROR(VLOOKUP($A11,参会名单!$A$2:$K$201,2,FALSE),"") -> 陈超芳 | C11: =IFERROR(VLOOKUP($A11,参会名单!$A$2:$K$201,3,FALSE),"") -> 万象云 | D11: =IFERROR(VLOOKUP($A11,参会名单!$A$2:$K$201,7,FALSE),"") -> VIP | E11: 未签到 | H11: 否
A12: 11 | B12: =IFERROR(VLOOKUP($A12,参会名单!$A$2:$K$201,2,FALSE),"") -> 高欣彤 | C12: =IFERROR(VLOOKUP($A12,参会名单!$A$2:$K$201,3,FALSE),"") -> 云栖智能 | D12: =IFERROR(VLOOKUP($A12,参会名单!$A$2:$K$201,7,FALSE),"") -> VIP | E12: 已签到 | F12: 0.36319444 | G12: 扫码 | H12: 否
A13: 12 | B13: =IFERROR(VLOOKUP($A13,参会名单!$A$2:$K$201,2,FALSE),"") -> 高宇丽 | C13: =IFERROR(VLOOKUP($A13,参会名单!$A$2:$K$201,3,FALSE),"") -> 智汇云 | D13: =IFERROR(VLOOKUP($A13,参会名单!$A$2:$K$201,7,FALSE),"") -> VIP | E13: 已签到 | F13: 0.35972222 | G13: 扫码 | H13: 是
A14: 13 | B14: =IFERROR(VLOOKUP($A14,参会名单!$A$2:$K$201,2,FALSE),"") -> 周军 | C14: =IFERROR(VLOOKUP($A14,参会名单!$A$2:$K$201,3,FALSE),"") -> 启元软件 | D14: =IFERROR(VLOOKUP($A14,参会名单!$A$2:$K$201,7,FALSE),"") -> VIP | E14: 已签到 | F14: 0.35902778 | G14: 人脸识别 | H14: 是
A15: 14 | B15: =IFERROR(VLOOKUP($A15,参会名单!$A$2:$K$201,2,FALSE),"") -> 周娟 | C15: =IFERROR(VLOOKUP($A15,参会名单!$A$2:$K$201,3,FALSE),"") -> 星瀚科技 | D15: =IFERROR(VLOOKUP($A15,参会名单!$A$2:$K$201,7,FALSE),"") -> VIP | E15: 已签到 | F15: 0.36805556 | G15: 人脸识别 | H15: 是
A16: 15 | B16: =IFERROR(VLOOKUP($A16,参会名单!$A$2:$K$201,2,FALSE),"") -> 唐宇泽 | C16: =IFERROR(VLOOKUP($A16,参会名单!$A$2:$K$201,3,FALSE),"") -> 智汇云 | D16: =IFERROR(VLOOKUP($A16,参会名单!$A$2:$K$201,7,FALSE),"") -> VIP | E16: 已签到 | F16: 0.3625 | G16: 扫码 | H16: 是
A17: 16 | B17: =IFERROR(VLOOKUP($A17,参会名单!$A$2:$K$201,2,FALSE),"") -> 何彤秀 | C17: =IFERROR(VLOOKUP($A17,参会名单!$A$2:$K$201,3,FALSE),"") -> 极光数据 | D17: =IFERROR(VLOOKUP($A17,参会名单!$A$2:$K$201,7,FALSE),"") -> VIP | E17: 未签到 | H17: 否
A18: 17 | B18: =IFERROR(VLOOKUP($A18,参会名单!$A$2:$K$201,2,FALSE),"") -> 林睿 | C18: =IFERROR(VLOOKUP($A18,参会名单!$A$2:$K$201,3,FALSE),"") -> 云栖智能 | D18: =IFERROR(VLOOKUP($A18,参会名单!$A$2:$K$201,7,FALSE),"") -> VIP | E18: 已签到 | F18: 0.36180556 | G18: 前台登记 | H18: 是
A19: 18 | B19: =IFERROR(VLOOKUP($A19,参会名单!$A$2:$K$201,2,FALSE),"") -> 黄涵军 | C19: =IFERROR(VLOOKUP($A19,参会名单!$A$2:$K$201,3,FALSE),"") -> 万象云 | D19: =IFERROR(VLOOKUP($A19,参会名单!$A$2:$K$201,7,FALSE),"") -> VIP | E19: 已签到 | F19: 0.3375 | G19: 扫码 | H19: 是
A20: 19 | B20: =IFERROR(VLOOKUP($A20,参会名单!$A$2:$K$201,2,FALSE),"") -> 王博 | C20: =IFERROR(VLOOKUP($A20,参会名单!$A$2:$K$201,3,FALSE),"") -> 智汇云 | D20: =IFERROR(VLOOKUP($A20,参会名单!$A$2:$K$201,7,FALSE),"") -> VIP | E20: 已签到 | F20: 0.34166667 | G20: 扫码 | H20: 是
A21: 20 | B21: =IFERROR(VLOOKUP($A21,参会名单!$A$2:$K$201,2,FALSE),"") -> 孙涛磊 | C21: =IFERROR(VLOOKUP($A21,参会名单!$A$2:$K$201,3,FALSE),"") -> 万象云 | D21: =IFERROR(VLOOKUP($A21,参会名单!$A$2:$K$201,7,FALSE),"") -> VIP | E21: 请假 | H21: 否
A22: 21 | B22: =IFERROR(VLOOKUP($A22,参会名单!$A$2:$K$201,2,FALSE),"") -> 蒋伟 | C22: =IFERROR(VLOOKUP($A22,参会名单!$A$2:$K$201,3,FALSE),"") -> 极光数据 | D22: =IFERROR(VLOOKUP($A22,参会名单!$A$2:$K$201,7,FALSE),"") -> VIP | E22: 已签到 | F22: 0.37083333 | G22: 扫码 | H22: 是
A23: 22 | B23: =IFERROR(VLOOKUP($A23,参会名单!$A$2:$K$201,2,FALSE),"") -> 林勇 | C23: =IFERROR(VLOOKUP($A23,参会名单!$A$2:$K$201,3,FALSE),"") -> 领航智造 | D23: =IFERROR(VLOOKUP($A23,参会名单!$A$2:$K$201,7,FALSE),"") -> VIP | E23: 已签到 | F23: 0.35694444 | G23: 扫码 | H23: 是
A24: 23 | B24: =IFERROR(VLOOKUP($A24,参会名单!$A$2:$K$201,2,FALSE),"") -> 唐泽 | C24: =IFERROR(VLOOKUP($A24,参会名单!$A$2:$K$201,3,FALSE),"") -> 蓝图网络 | D24: =IFERROR(VLOOKUP($A24,参会名单!$A$2:$K$201,7,FALSE),"") -> VIP | E24: 已签到 | F24: 0.35694444 | G24: 扫码 | H24: 是
A25: 24 | B25: =IFERROR(VLOOKUP($A25,参会名单!$A$2:$K$201,2,FALSE),"") -> 郭芳平 | C25: =IFERROR(VLOOKUP($A25,参会名单!$A$2:$K$201,3,FALSE),"") -> 深蓝计算 | D25: =IFERROR(VLOOKUP($A25,参会名单!$A$2:$K$201,7,FALSE),"") -> VIP | E25: 已签到 | F25: 0.35 | G25: 扫码 | H25: 是
A26: 25 | B26: =IFERROR(VLOOKUP($A26,参会名单!$A$2:$K$201,2,FALSE),"") -> 谢琪娟 | C26: =IFERROR(VLOOKUP($A26,参会名单!$A$2:$K$201,3,FALSE),"") -> 星瀚科技 | D26: =IFERROR(VLOOKUP($A26,参会名单!$A$2:$K$201,7,FALSE),"") -> VIP | E26: 已签到 | F26: 0.35 | G26: 人脸识别 | H26: 是
A27: 26 | B27: =IFERROR(VLOOKUP($A27,参会名单!$A$2:$K$201,2,FALSE),"") -> 董超 | C27: =IFERROR(VLOOKUP($A27,参会名单!$A$2:$K$201,3,FALSE),"") -> 云栖智能 | D27: =IFERROR(VLOOKUP($A27,参会名单!$A$2:$K$201,7,FALSE),"") -> VIP | E27: 已签到 | F27: 0.33472222 | G27: 人脸识别 | H27: 是
A28: 27 | B28: =IFERROR(VLOOKUP($A28,参会名单!$A$2:$K$201,2,FALSE),"") -> 黄洋 | C28: =IFERROR(VLOOKUP($A28,参会名单!$A$2:$K$201,3,FALSE),"") -> 智汇云 | D28: =IFERROR(VLOOKUP($A28,参会名单!$A$2:$K$201,7,FALSE),"") -> VIP | E28: 已签到 | F28: 0.35486111 | G28: 扫码 | H28: 是
A29: 28 | B29: =IFERROR(VLOOKUP($A29,参会名单!$A$2:$K$201,2,FALSE),"") -> 冯嘉杰 | C29: =IFERROR(VLOOKUP($A29,参会名单!$A$2:$K$201,3,FALSE),"") -> 智汇云 | D29: =IFERROR(VLOOKUP($A29,参会名单!$A$2:$K$201,7,FALSE),"") -> VIP | E29: 已签到 | F29: 0.36805556 | G29: 扫码 | H29: 是
A30: 29 | B30: =IFERROR(VLOOKUP($A30,参会名单!$A$2:$K$201,2,FALSE),"") -> 赵洋泽 | C30: =IFERROR(VLOOKUP($A30,参会名单!$A$2:$K$201,3,FALSE),"") -> 星瀚科技 | D30: =IFERROR(VLOOKUP($A30,参会名单!$A$2:$K$201,7,FALSE),"") -> VIP | E30: 已签到 | F30: 0.34583333 | G30: 扫码 | H30: 否
A31: 30 | B31: =IFERROR(VLOOKUP($A31,参会名单!$A$2:$K$201,2,FALSE),"") -> 吴磊 | C31: =IFERROR(VLOOKUP($A31,参会名单!$A$2:$K$201,3,FALSE),"") -> 天工智能 | D31: =IFERROR(VLOOKUP($A31,参会名单!$A$2:$K$201,7,FALSE),"") -> VIP | E31: 已签到 | F31: 0.36944444 | G31: 人脸识别 | H31: 否
A32: 31 | B32: =IFERROR(VLOOKUP($A32,参会名单!$A$2:$K$201,2,FALSE),"") -> 郑明 | C32: =IFERROR(VLOOKUP($A32,参会名单!$A$2:$K$201,3,FALSE),"") -> 领航智造 | D32: =IFERROR(VLOOKUP($A32,参会名单!$A$2:$K$201,7,FALSE),"") -> 标准 | E32: 已签到 | F32: 0.40625 | G32: 扫码 | H32: 是
A33: 32 | B33: =IFERROR(VLOOKUP($A33,参会名单!$A$2:$K$201,2,FALSE),"") -> 梁艳伟 | C33: =IFERROR(VLOOKUP($A33,参会名单!$A$2:$K$201,3,FALSE),"") -> 蜂巢科技 | D33: =IFERROR(VLOOKUP($A33,参会名单!$A$2:$K$201,7,FALSE),"") -> 标准 | E33: 已签到 | F33: 0.34305556 | G33: 扫码 | H33: 是
... A35: 34 | B35: =IFERROR(VLOOKUP($A35,参会名单!$A$2:$K$201,2,FALSE),"") -> 徐敏文 | C35: =IFERROR(VLOOKUP($A35,参会名单!$A$2:$K$201,3,FALSE),"") -> 云栖智能 | D35: =IFERROR(VLOOKUP($A35,参会名单!$A$2:$K$201,7,FALSE),"") -> 标准 | E35: 已签到 | F35: 0.38680556 | G35: 人脸识别 | H35: 是
A36: 35 | B36: =IFERROR(VLOOKUP($A36,参会名单!$A$2:$K$201,2,FALSE),"") -> 潘涵杰 | C36: =IFERROR(VLOOKUP($A36,参会名单!$A$2:$K$201,3,FALSE),"") -> 极光数据 | D36: =IFERROR(VLOOKUP($A36,参会名单!$A$2:$K$201,7,FALSE),"") -> 标准 | E36: 请假 | H36: 否
A37: 36 | B37: =IFERROR(VLOOKUP($A37,参会名单!$A$2:$K$201,2,FALSE),"") -> 刘涵 | C37: =IFERROR(VLOOKUP($A37,参会名单!$A$2:$K$201,3,FALSE),"") -> 云栖智能 | D37: =IFERROR(VLOOKUP($A37,参会名单!$A$2:$K$201,7,FALSE),"") -> 标准 | E37: 已签到 | F37: 0.36944444 | G37: 扫码 | H37: 是
A38: 37 | B38: =IFERROR(VLOOKUP($A38,参会名单!$A$2:$K$201,2,FALSE),"") -> 张彤 | C38: =IFERROR(VLOOKUP($A38,参会名单!$A$2:$K$201,3,FALSE),"") -> 星瀚科技 | D38: =IFERROR(VLOOKUP($A38,参会名单!$A$2:$K$201,7,FALSE),"") -> 标准 | E38: 已签到 | F38: 0.38263889 | G38: 扫码 | H38: 是
A39: 38 | B39: =IFERROR(VLOOKUP($A39,参会名单!$A$2:$K$201,2,FALSE),"") -> 林勇明 | C39: =IFERROR(VLOOKUP($A39,参会名单!$A$2:$K$201,3,FALSE),"") -> 智汇云 | D39: =IFERROR(VLOOKUP($A39,参会名单!$A$2:$K$201,7,FALSE),"") -> 标准 | E39: 已签到 | F39: 0.40486111 | G39: 人脸识别 | H39: 是
A40: 39 | B40: =IFERROR(VLOOKUP($A40,参会名单!$A$2:$K$201,2,FALSE),"") -> 唐艳浩 | C40: =IFERROR(VLOOKUP($A40,参会名单!$A$2:$K$201,3,FALSE),"") -> 星环动力 | D40: =IFERROR(VLOOKUP($A40,参会名单!$A$2:$K$201,7,FALSE),"") -> 标准 | E40: 已签到 | F40: 0.33958333 | G40: 前台登记 | H40: 是
A41: 40 | B41: =IFERROR(VLOOKUP($A41,参会名单!$A$2:$K$201,2,FALSE),"") -> 马静娟 | C41: =IFERROR(VLOOKUP($A41,参会名单!$A$2:$K$201,3,FALSE),"") -> 星瀚科技 | D41: =IFERROR(VLOOKUP($A41,参会名单!$A$2:$K$201,7,FALSE),"") -> 标准 | E41: 已签到 | F41: 0.35416667 | G41: 人脸识别 | H41: 是
...

Sheet 数据统计
A1: TechVision 2026 全球开发者峰会 · 签到数据统计
A2: 2026 年 5 月 20 日 · 深圳国际会展中心 5 号馆 | 数据口径：签到追踪表全量记录（含请假）
A4: 一、到场概览
A5: 总报名人数 | C5: 已签到 | E5: 未签到 | G5: 到场率
A6: =COUNTA(参会名单!$A$2:$A$201) -> 200 | C6: =COUNTIF('签到追踪表'!$E$2:$E$201,"已签到") -> 166 | E6: =COUNTIF('签到追踪表'!$E$2:$E$201,"未签到") -> 28 | G6: =IF(OR($A$6="",$A$6=0),"",$C$6/$A$6) -> 0.83
A8: 二、票种分布与到场率
A9: 票种 | B9: 报名人数 | C9: 已签到 | D9: 未签到 | E9: 请假 | F9: 到场率 | G9: 报名占比
A10: VIP | B10: =COUNTIF(参会名单!$G$2:$G$201,$A10) -> 30 | C10: =COUNTIFS(参会名单!$G$2:$G$201,$A10,'签到追踪表'!$E$2:$E$201,"已签到") -> 27 | D10: =COUNTIFS(参会名单!$G$2:$G$201,$A10,'签到追踪表'!$E$2:$E$201,"未签到") -> 2 | E10: =COUNTIFS(参会名单!$G$2:$G$201,$A10,'签到追踪表'!$E$2:$E$201,"请假") -> 1 | F10: =IF(OR(B10="",B10=0),"",C10/B10) -> 0.9 | G10: =IF(OR($B$14="",$B$14=0),"",B10/$B$14) -> 0.15
A11: 标准 | B11: =COUNTIF(参会名单!$G$2:$G$201,$A11) -> 120 | C11: =COUNTIFS(参会名单!$G$2:$G$201,$A11,'签到追踪表'!$E$2:$E$201,"已签到") -> 96 | D11: =COUNTIFS(参会名单!$G$2:$G$201,$A11,'签到追踪表'!$E$2:$E$201,"未签到") -> 20 | E11: =COUNTIFS(参会名单!$G$2:$G$201,$A11,'签到追踪表'!$E$2:$E$201,"请假") -> 4 | F11: =IF(OR(B11="",B11=0),"",C11/B11) -> 0.8 | G11: =IF(OR($B$14="",$B$14=0),"",B11/$B$14) -> 0.6
A12: 学生 | B12: =COUNTIF(参会名单!$G$2:$G$201,$A12) -> 30 | C12: =COUNTIFS(参会名单!$G$2:$G$201,$A12,'签到追踪表'!$E$2:$E$201,"已签到") -> 24 | D12: =COUNTIFS(参会名单!$G$2:$G$201,$A12,'签到追踪表'!$E$2:$E$201,"未签到") -> 5 | E12: =COUNTIFS(参会名单!$G$2:$G$201,$A12,'签到追踪表'!$E$2:$E$201,"请假") -> 1 | F12: =IF(OR(B12="",B12=0),"",C12/B12) -> 0.8 | G12: =IF(OR($B$14="",$B$14=0),"",B12/$B$14) -> 0.15
A13: 赞助商 | B13: =COUNTIF(参会名单!$G$2:$G$201,$A13) -> 20 | C13: =COUNTIFS(参会名单!$G$2:$G$201,$A13,'签到追踪表'!$E$2:$E$201,"已签到") -> 19 | D13: =COUNTIFS(参会名单!$G$2:$G$201,$A13,'签到追踪表'!$E$2:$E$201,"未签到") -> 1 | E13: =COUNTIFS(参会名单!$G$2:$G$201,$A13,'签到追踪表'!$E$2:$E$201,"请假") -> 0 | F13: =IF(OR(B13="",B13=0),"",C13/B13) -> 0.95 | G13: =IF(OR($B$14="",$B$14=0),"",B13/$B$14) -> 0.1
A14: 合计 | B14: =SUM(B10:B13) -> 200 | C14: =SUM(C10:C13) -> 166 | D14: =SUM(D10:D13) -> 28 | E14: =SUM(E10:E13) -> 6 | F14: =IF(OR(B14="",B14=0),"",C14/B14) -> 0.83 | G14: =SUM(G10:G13) -> 1
A16: 三、公司分布（按报名人数 Top 12，含高校）
A17: 公司 / 院校 | B17: 报名人数 | C17: 已签到 | D17: 到场率 | E17: 占全部报名
A18: 星瀚科技 | B18: =COUNTIF(参会名单!$C$2:$C$201,$A18) -> 20 | C18: =COUNTIFS(参会名单!$C$2:$C$201,$A18,'签到追踪表'!$E$2:$E$201,"已签到") -> 18 | D18: =IF(OR(B18="",B18=0),"",C18/B18) -> 0.9 | E18: =IF(OR($A$6="",$A$6=0),"",B18/$A$6) -> 0.1
A19: 云栖智能 | B19: =COUNTIF(参会名单!$C$2:$C$201,$A19) -> 20 | C19: =COUNTIFS(参会名单!$C$2:$C$201,$A19,'签到追踪表'!$E$2:$E$201,"已签到") -> 18 | D19: =IF(OR(B19="",B19=0),"",C19/B19) -> 0.9 | E19: =IF(OR($A$6="",$A$6=0),"",B19/$A$6) -> 0.1
A20: 领航智造 | B20: =COUNTIF(参会名单!$C$2:$C$201,$A20) -> 18 | C20: =COUNTIFS(参会名单!$C$2:$C$201,$A20,'签到追踪表'!$E$2:$E$201,"已签到") -> 16 | D20: =IF(OR(B20="",B20=0),"",C20/B20) -> 0.88888889 | E20: =IF(OR($A$6="",$A$6=0),"",B20/$A$6) -> 0.09
A21: 蓝图网络 | B21: =COUNTIF(参会名单!$C$2:$C$201,$A21) -> 18 | C21: =COUNTIFS(参会名单!$C$2:$C$201,$A21,'签到追踪表'!$E$2:$E$201,"已签到") -> 15 | D21: =IF(OR(B21="",B21=0),"",C21/B21) -> 0.83333333 | E21: =IF(OR($A$6="",$A$6=0),"",B21/$A$6) -> 0.09
A22: 智汇云 | B22: =COUNTIF(参会名单!$C$2:$C$201,$A22) -> 16 | C22: =COUNTIFS(参会名单!$C$2:$C$201,$A22,'签到追踪表'!$E$2:$E$201,"已签到") -> 14 | D22: =IF(OR(B22="",B22=0),"",C22/B22) -> 0.875 | E22: =IF(OR($A$6="",$A$6=0),"",B22/$A$6) -> 0.08
A23: 蜂巢科技 | B23: =COUNTIF(参会名单!$C$2:$C$201,$A23) -> 16 | C23: =COUNTIFS(参会名单!$C$2:$C$201,$A23,'签到追踪表'!$E$2:$E$201,"已签到") -> 14 | D23: =IF(OR(B23="",B23=0),"",C23/B23) -> 0.875 | E23: =IF(OR($A$6="",$A$6=0),"",B23/$A$6) -> 0.08
A24: 南粤科技大学 | B24: =COUNTIF(参会名单!$C$2:$C$201,$A24) -> 12 | C24: =COUNTIFS(参会名单!$C$2:$C$201,$A24,'签到追踪表'!$E$2:$E$201,"已签到") -> 11 | D24: =IF(OR(B24="",B24=0),"",C24/B24) -> 0.91666667 | E24: =IF(OR($A$6="",$A$6=0),"",B24/$A$6) -> 0.06
A25: 湾区信息学院 | B25: =COUNTIF(参会名单!$C$2:$C$201,$A25) -> 10 | C25: =COUNTIFS(参会名单!$C$2:$C$201,$A25,'签到追踪表'!$E$2:$E$201,"已签到") -> 7 | D25: =IF(OR(B25="",B25=0),"",C25/B25) -> 0.7 | E25: =IF(OR($A$6="",$A$6=0),"",B25/$A$6) -> 0.05
A26: 光合数字 | B26: =COUNTIF(参会名单!$C$2:$C$201,$A26) -> 8 | C26: =COUNTIFS(参会名单!$C$2:$C$201,$A26,'签到追踪表'!$E$2:$E$201,"已签到") -> 6 | D26: =IF(OR(B26="",B26=0),"",C26/B26) -> 0.75 | E26: =IF(OR($A$6="",$A$6=0),"",B26/$A$6) -> 0.04
A27: 鹏城理工学院 | B27: =COUNTIF(参会名单!$C$2:$C$201,$A27) -> 8 | C27: =COUNTIFS(参会名单!$C$2:$C$201,$A27,'签到追踪表'!$E$2:$E$201,"已签到") -> 6 | D27: =IF(OR(B27="",B27=0),"",C27/B27) -> 0.75 | E27: =IF(OR($A$6="",$A$6=0),"",B27/$A$6) -> 0.04
A28: 南岭智联 | B28: =COUNTIF(参会名单!$C$2:$C$201,$A28) -> 7 | C28: =COUNTIFS(参会名单!$C$2:$C$201,$A28,'签到追踪表'!$E$2:$E$201,"已签到") -> 5 | D28: =IF(OR(B28="",B28=0),"",C28/B28) -> 0.71428571 | E28: =IF(OR($A$6="",$A$6=0),"",B28/$A$6) -> 0.035
A29: 天工智能 | B29: =COUNTIF(参会名单!$C$2:$C$201,$A29) -> 7 | C29: =COUNTIFS(参会名单!$C$2:$C$201,$A29,'签到追踪表'!$E$2:$E$201,"已签到") -> 7 | D29: =IF(OR(B29="",B29=0),"",C29/B29) -> 1 | E29: =IF(OR($A$6="",$A$6=0),"",B29/$A$6) -> 0.035
A30: 小计（Top 12） | B30: =SUM(B18:B29) -> 160 | C30: =SUM(C18:C29) -> 137 | D30: =IF(OR(B30="",B30=0),"",C30/B30) -> 0.85625 | E30: =SUM(E18:E29) -> 0.8
A32: 四、餐食偏好（按报名人数，供餐饮备货）
A33: 餐食类型 | B33: 人数 | C33: 占比
A34: 标准 | B34: =COUNTIF(参会名单!$H$2:$H$201,$A34) -> 128 | C34: =IF(OR($B$38="",$B$38=0),"",B34/$B$38) -> 0.64
A35: 素食 | B35: =COUNTIF(参会名单!$H$2:$H$201,$A35) -> 36 | C35: =IF(OR($B$38="",$B$38=0),"",B35/$B$38) -> 0.18
A36: 清真 | B36: =COUNTIF(参会名单!$H$2:$H$201,$A36) -> 24 | C36: =IF(OR($B$38="",$B$38=0),"",B36/$B$38) -> 0.12
A37: 无麸质 | B37: =COUNTIF(参会名单!$H$2:$H$201,$A37) -> 12 | C37: =IF(OR($B$38="",$B$38=0),"",B37/$B$38) -> 0.06
A38: 合计 | B38: =SUM(B34:B37) -> 200 | C38: =SUM(C34:C37) -> 1
A40: 五、T恤尺码（按报名人数，供服装制版）
A41: 尺码 | B41: 数量 | C41: 占比
A42: S | B42: =COUNTIF(参会名单!$I$2:$I$201,$A42) -> 20 | C42: =IF(OR($B$47="",$B$47=0),"",B42/$B$47) -> 0.1
A43: M | B43: =COUNTIF(参会名单!$I$2:$I$201,$A43) -> 70 | C43: =IF(OR($B$47="",$B$47=0),"",B43/$B$47) -> 0.35
A44: L | B44: =COUNTIF(参会名单!$I$2:$I$201,$A44) -> 80 | C44: =IF(OR($B$47="",$B$47=0),"",B44/$B$47) -> 0.4
A45: XL | B45: =COUNTIF(参会名单!$I$2:$I$201,$A45) -> 26 | C45: =IF(OR($B$47="",$B$47=0),"",B45/$B$47) -> 0.13
...

Sheet 物资清单
A1: 序号 | B1: 物资名称 | C1: 类别 | D1: 规格 | E1: 需求数量 | F1: 已准备 | G1: 差额 | H1: 状态 | I1: 负责人 | J1: 备注
A2: 1 | B2: 胸牌 + 挂绳 | C2: 物料 | D2: 标准 90×130mm | E2: =数据统计!$A$6 -> 200 | F2: 210 | G2: =F2-E2 -> 10 | H2: =IF(G2<0,"待补货",IF(G2=0,"已就绪","充足")) -> 充足 | I2: 行政组 | J2: 按报名人数备货，含 5% 冗余
A3: 2 | B3: 手提袋 | C3: 物料 | D3: 帆布 | E3: =数据统计!$A$6 -> 200 | F3: 180 | G3: =F3-E3 -> -20 | H3: =IF(G3<0,"待补货",IF(G3=0,"已就绪","充足")) -> 待补货 | I3: 行政组 | J3: 供应商延期，需补货
A4: 3 | B4: 会议手册 | C4: 资料 | D4: A5 骑马钉 32P | E4: =数据统计!$A$6 -> 200 | F4: 200 | G4: =F4-E4 -> 0 | H4: =IF(G4<0,"待补货",IF(G4=0,"已就绪","充足")) -> 已就绪 | I4: 内容组
A5: 4 | B5: 伴手礼 | C5: 礼品 | D5: 定制保温杯 | E5: =数据统计!$C$6 -> 166 | F5: 170 | G5: =F5-E5 -> 4 | H5: =IF(G5<0,"待补货",IF(G5=0,"已就绪","充足")) -> 充足 | I5: 市场组 | J5: 按已签到人数发放
A6: 5 | B6: 午餐券-标准 | C6: 餐饮 | D6: 标准餐 | E6: =数据统计!$B$34 -> 128 | F6: 128 | G6: =F6-E6 -> 0 | H6: =IF(G6<0,"待补货",IF(G6=0,"已就绪","充足")) -> 已就绪 | I6: 餐饮组
A7: 6 | B7: 午餐券-素食 | C7: 餐饮 | D7: 素食餐 | E7: =数据统计!$B$35 -> 36 | F7: 36 | G7: =F7-E7 -> 0 | H7: =IF(G7<0,"待补货",IF(G7=0,"已就绪","充足")) -> 已就绪 | I7: 餐饮组
A8: 7 | B8: 午餐券-清真 | C8: 餐饮 | D8: 清真餐 | E8: =数据统计!$B$36 -> 24 | F8: 20 | G8: =F8-E8 -> -4 | H8: =IF(G8<0,"待补货",IF(G8=0,"已就绪","充足")) -> 待补货 | I8: 餐饮组 | J8: 缺口 4 份，供应商确认中
A9: 8 | B9: 午餐券-无麸质 | C9: 餐饮 | D9: 无麸质餐 | E9: =数据统计!$B$37 -> 12 | F9: 12 | G9: =F9-E9 -> 0 | H9: =IF(G9<0,"待补货",IF(G9=0,"已就绪","充足")) -> 已就绪 | I9: 餐饮组
A10: 9 | B10: T恤-S | C10: 服装 | D10: 纯棉 180g | E10: =数据统计!$B$42 -> 20 | F10: 20 | G10: =F10-E10 -> 0 | H10: =IF(G10<0,"待补货",IF(G10=0,"已就绪","充足")) -> 已就绪 | I10: 行政组
A11: 10 | B11: T恤-M | C11: 服装 | D11: 纯棉 180g | E11: =数据统计!$B$43 -> 70 | F11: 70 | G11: =F11-E11 -> 0 | H11: =IF(G11<0,"待补货",IF(G11=0,"已就绪","充足")) -> 已就绪 | I11: 行政组
A12: 11 | B12: T恤-L | C12: 服装 | D12: 纯棉 180g | E12: =数据统计!$B$44 -> 80 | F12: 72 | G12: =F12-E12 -> -8 | H12: =IF(G12<0,"待补货",IF(G12=0,"已就绪","充足")) -> 待补货 | I12: 行政组 | J12: L 码偏紧，需补 8 件
A13: 12 | B13: T恤-XL | C13: 服装 | D13: 纯棉 180g | E13: =数据统计!$B$45 -> 26 | F13: 26 | G13: =F13-E13 -> 0 | H13: =IF(G13<0,"待补货",IF(G13=0,"已就绪","充足")) -> 已就绪 | I13: 行政组
A14: 13 | B14: T恤-XXL | C14: 服装 | D14: 纯棉 180g | E14: =数据统计!$B$46 -> 4 | F14: 6 | G14: =F14-E14 -> 2 | H14: =IF(G14<0,"待补货",IF(G14=0,"已就绪","充足")) -> 充足 | I14: 行政组
A15: 14 | B15: 矿泉水 | C15: 餐饮 | D15: 550ml × 24 瓶/箱 | E15: =ROUNDUP(数据统计!$A$6*2/24,0) -> 17 | F15: 17 | G15: =F15-E15 -> 0 | H15: =IF(G15<0,"待补货",IF(G15=0,"已就绪","充足")) -> 已就绪 | I15: 行政组 | J15: 按人均 2 瓶折算箱数
A16: 15 | B16: 签到设备 | C16: 设备 | D16: 扫码枪 + 平板 | E16: 6 | F16: 8 | G16: =F16-E16 -> 2 | H16: =IF(G16<0,"待补货",IF(G16=0,"已就绪","充足")) -> 充足 | I16: 技术组 | J16: 含 2 台备用
